Workbook

Sheet รวมตาราง จ.อ่างทอง
A1: แบบรายงานสถานการณ์อุทกภัย จังหวัดอ่างทอง ปี 2569
B2: ** ขอให้สถานบริการบันทึกข้อมูล ภายในเวลา 14.00 น. ของทุกวัน **
A4: 1. สถานบริการสาธารณสุขที่ได้รับผลกระทบ จำนวน ..........-........ แห่ง (สถานบริการ หมายถึง สสจ. สสอ. รพศ. รพท. รพช. รพ.สต.และสถานบริการสังกัดกรมหรืออื่นๆ) | J4: ** สถานบริการบันทึก **
A6: ที่ | B6: ชื่อสถานบริการ | D6: ผลกระทบที่ได้รับ | E6: สถานะการให้บริการ | G6: ชื่อสถานที่ที่ให้บริการทดแทน (กรณี ปิดให้บริการ) | L6: จำนวน (ครั้ง) | M6: เยี่ยมบ้าน (ราย) | N6: จ่ายยา (ราย) | O6: ให้บริการสุขศึกษา (ราย) | P6: ตรวจรักษา (ราย) | Q6: คัดกรองสุขภาพจิต (ราย) | R6: การส่งต่อ (ราย)
E7: เปิดบางส่วน | F7: ปิดบริการ | L7: วิเศษชัยชาญ | M7: 212 | N7: 212 | O7: 212 | P7: 0 | Q7: 0 | R7: 0
A8: 1 | L8: ไชโย | M8: 20 | N8: 10 | O8: 11 | P8: 0 | Q8: 0 | R8: 0
A9: 2 | L9: ป่าโมก | M9: 20 | N9: 0 | O9: 25 | P9: 0 | Q9: 17 | R9: 0
A10: 3
A11: 4
A12: 5
A14: 2. การดูแลกลุ่มเปราะบาง ** สถานบริการบันทึก **
A16: วันที่ | B16: ผู้ป่วยติดเตียง | G16: ผู้ป่วยฟอกไต | L16: จิตเวช (ที่ต้องรับยา) | Q16: ผู้สูงอายุ | W16: ผู้พิการ | AB16: ผู้ป่วยโรคเรื้อรัง (NCD) | AG16: หญิงตั้งครรภ์ | AL16: เด็กอายุ (0-5 ปี)
B17: จำนวนทั้งหมดในหมู่ (ราย) | C17: จำนวนในพื้นที่ที่น้ำท่วม (ราย) | D17: การให้ความช่วยเหลือ (ราย) | G17: จำนวนทั้งหมดในหมู่ (ราย) | H17: จำนวนในพื้นที่ที่น้ำท่วม (ราย) | I17: การให้ความช่วยเหลือ (ราย) | K17: ผู้ป่วยฟอกไตในพื้นที่น้ำท่วม | L17: จำนวนทั้งหมดในหมู่ (ราย) | M17: จำนวนในพื้นที่ที่น้ำท่วม (ราย) | N17: การให้ความช่วยเหลือ (ราย) | P17: จิตเวช (ที่ต้องรับยา)ในพื้นที่น้ำท่วม | Q17: จำนวนทั้งหมดในหมู่ (ราย) | R17: จำนวนในพื้นที่ที่น้ำท่วม (ราย) | S17: การให้ความช่วยเหลือ (ราย) | U17: ผู้สูงอายุที่มีโรคประจำตัวในพื้นที่น้ำท่วม | W17: จำนวนทั้งหมดในหมู่ (ราย) | X17: จำนวนในพื้นที่ที่น้ำท่วม (ราย) | Y17: การให้ความช่วยเหลือ (ราย) | AA17: ผู้พิการในพื้นที่น้ำท่วม | AB17: จำนวนทั้งหมดในหมู่ (ราย) | AC17: จำนวนในพื้นที่ที่น้ำท่วม (ราย) | AD17: การให้ความช่วยเหลือ (ราย) | AF17: ผู้ป่วยโรคเรื้อรัง (NCD)ในพื้นที่น้ำท่วม | AG17: จำนวนทั้งหมดในหมู่ (ราย) | AH17: จำนวนในพื้นที่ที่น้ำท่วม (ราย) | AI17: การให้ความช่วยเหลือ (ราย) | AK17: หญิงตั้งครรภ์ในพื้นที่น้ำท่วม | AL17: จำนวนทั้งหมดในหมู่ (ราย) | AM17: จำนวนในพื้นที่ที่น้ำท่วม (ราย) | AN17: การให้ความช่วยเหลือ (ราย) | AP17: เด็กอายุ (0-5 ปี) ในพื้นที่น้ำท่วม
D18: อยู่บ้าน (ราย) | E18: ศูนย์พักพิง (ราย) | F18: ส่งต่อ รพ. (ราย) | I18: อยู่บ้าน (ราย) | J18: อพยพ (ราย) | K18: ขาดการฟอกไต (ราย) | N18: อยู่บ้าน (ราย) | O18: อพยพ (ราย) | P18: พบปัญหาด้านสุขภาพ (ราย) | S18: อยู่บ้าน (ราย) | T18: อพยพ (ราย) | U18: จำนวนทั้งหมด (ราย) | V18: ขาดยา (ราย) | Y18: อยู่บ้าน (ราย) | Z18: อพยพ (ราย) | AA18: พบปัญหาด้านสุขภาพ (ราย) | AD18: อยู่บ้าน (ราย) | AE18: อพยพ (ราย) | AF18: ขาดยา (ราย) | AI18: อยู่บ้าน (ราย) | AJ18: อพยพ (ราย) | AK18: พบปัญหาด้านสุขภาพ (ราย) | AN18: อยู่บ้าน (ราย) | AO18: อพยพ (ราย) | AP18: พบปัญหาด้านสุขภาพ (ราย)
A19: 25475 | B19: ='เมือง'!B19+'ป่าโมก'!B19+'โพธิ์ทอง'!B19+'วิเศษ'!B19+'สามโก้'!B19+'แสวงหา'!B19+'ไชโย'!B19 -> 0
A20: 25476 | B20: ='เมือง'!B20+'ป่าโมก'!B20+'โพธิ์ทอง'!B20+'วิเศษ'!B20+'สามโก้'!B20+'แสวงหา'!B20+'ไชโย'!B20 -> 236 | C20: ='เมือง'!C20+'ป่าโมก'!C20+'โพธิ์ทอง'!C20+'วิเศษ'!C20+'สามโก้'!C20+'แสวงหา'!C20+'ไชโย'!C20 -> 78 | D20: ='เมือง'!D20+'ป่าโมก'!D20+'โพธิ์ทอง'!D20+'วิเศษ'!D20+'สามโก้'!D20+'แสวงหา'!D20+'ไชโย'!D20 -> 42 | E20: ='เมือง'!E20+'ป่าโมก'!E20+'โพธิ์ทอง'!E20+'วิเศษ'!E20+'สามโก้'!E20+'แสวงหา'!E20+'ไชโย'!E20 -> 0 | F20: ='เมือง'!F20+'ป่าโมก'!F20+'โพธิ์ทอง'!F20+'วิเศษ'!F20+'สามโก้'!F20+'แสวงหา'!F20+'ไชโย'!F20 -> 0 | G20: ='เมือง'!G20+'ป่าโมก'!G20+'โพธิ์ทอง'!G20+'วิเศษ'!G20+'สามโก้'!G20+'แสวงหา'!G20+'ไชโย'!G20 -> 22 | H20: ='เมือง'!H20+'ป่าโมก'!H20+'โพธิ์ทอง'!H20+'วิเศษ'!H20+'สามโก้'!H20+'แสวงหา'!H20+'ไชโย'!H20 -> 1 | I20: ='เมือง'!I20+'ป่าโมก'!I20+'โพธิ์ทอง'!I20+'วิเศษ'!I20+'สามโก้'!I20+'แสวงหา'!I20+'ไชโย'!I20 -> 1 | ... AP20: ='เมือง'!AP20+'ป่าโมก'!AP20+'โพธิ์ทอง'!AP20+'วิเศษ'!AP20+'สามโก้'!AP20+'แสวงหา'!AP20+'ไชโย'!AP20 -> 0
A21: 25477 | B21: ='เมือง'!B21+'ป่าโมก'!B21+'โพธิ์ทอง'!B21+'วิเศษ'!B21+'สามโก้'!B21+'แสวงหา'!B21+'ไชโย'!B21 -> 214 | C21: ='เมือง'!C21+'ป่าโมก'!C21+'โพธิ์ทอง'!C21+'วิเศษ'!C21+'สามโก้'!C21+'แสวงหา'!C21+'ไชโย'!C21 -> 39 | D21: ='เมือง'!D21+'ป่าโมก'!D21+'โพธิ์ทอง'!D21+'วิเศษ'!D21+'สามโก้'!D21+'แสวงหา'!D21+'ไชโย'!D21 -> 39 | E21: ='เมือง'!E21+'ป่าโมก'!E21+'โพธิ์ทอง'!E21+'วิเศษ'!E21+'สามโก้'!E21+'แสวงหา'!E21+'ไชโย'!E21 -> 0 | F21: ='เมือง'!F21+'ป่าโมก'!F21+'โพธิ์ทอง'!F21+'วิเศษ'!F21+'สามโก้'!F21+'แสวงหา'!F21+'ไชโย'!F21 -> 0 | G21: ='เมือง'!G21+'ป่าโมก'!G21+'โพธิ์ทอง'!G21+'วิเศษ'!G21+'สามโก้'!G21+'แสวงหา'!G21+'ไชโย'!G21 -> 22 | H21: ='เมือง'!H21+'ป่าโมก'!H21+'โพธิ์ทอง'!H21+'วิเศษ'!H21+'สามโก้'!H21+'แสวงหา'!H21+'ไชโย'!H21 -> 1 | I21: ='เมือง'!I21+'ป่าโมก'!I21+'โพธิ์ทอง'!I21+'วิเศษ'!I21+'สามโก้'!I21+'แสวงหา'!I21+'ไชโย'!I21 -> 2 | ... AP21: ='เมือง'!AP21+'ป่าโมก'!AP21+'โพธิ์ทอง'!AP21+'วิเศษ'!AP21+'สามโก้'!AP21+'แสวงหา'!AP21+'ไชโย'!AP21 -> 0
A22: 25478 | B22: ='เมือง'!B22+'ป่าโมก'!B22+'โพธิ์ทอง'!B22+'วิเศษ'!B22+'สามโก้'!B22+'แสวงหา'!B22+'ไชโย'!B22 -> 50 | C22: ='เมือง'!C22+'ป่าโมก'!C22+'โพธิ์ทอง'!C22+'วิเศษ'!C22+'สามโก้'!C22+'แสวงหา'!C22+'ไชโย'!C22 -> 1 | D22: ='เมือง'!D22+'ป่าโมก'!D22+'โพธิ์ทอง'!D22+'วิเศษ'!D22+'สามโก้'!D22+'แสวงหา'!D22+'ไชโย'!D22 -> 1 | E22: ='เมือง'!E22+'ป่าโมก'!E22+'โพธิ์ทอง'!E22+'วิเศษ'!E22+'สามโก้'!E22+'แสวงหา'!E22+'ไชโย'!E22 -> 0 | F22: ='เมือง'!F22+'ป่าโมก'!F22+'โพธิ์ทอง'!F22+'วิเศษ'!F22+'สามโก้'!F22+'แสวงหา'!F22+'ไชโย'!F22 -> 0 | G22: ='เมือง'!G22+'ป่าโมก'!G22+'โพธิ์ทอง'!G22+'วิเศษ'!G22+'สามโก้'!G22+'แสวงหา'!G22+'ไชโย'!G22 -> 6 | H22: ='เมือง'!H22+'ป่าโมก'!H22+'โพธิ์ทอง'!H22+'วิเศษ'!H22+'สามโก้'!H22+'แสวงหา'!H22+'ไชโย'!H22 -> 0 | I22: ='เมือง'!I22+'ป่าโมก'!I22+'โพธิ์ทอง'!I22+'วิเศษ'!I22+'สามโก้'!I22+'แสวงหา'!I22+'ไชโย'!I22 -> 0 | ... AP22: ='เมือง'!AP22+'ป่าโมก'!AP22+'โพธิ์ทอง'!AP22+'วิเศษ'!AP22+'สามโก้'!AP22+'แสวงหา'!AP22+'ไชโย'!AP22 -> 0
A23: 25479 | B23: ='เมือง'!B23+'ป่าโมก'!B23+'โพธิ์ทอง'!B23+'วิเศษ'!B23+'สามโก้'!B23+'แสวงหา'!B23+'ไชโย'!B23 -> 0 | C23: ='เมือง'!C23+'ป่าโมก'!C23+'โพธิ์ทอง'!C23+'วิเศษ'!C23+'สามโก้'!C23+'แสวงหา'!C23+'ไชโย'!C23 -> 0 | D23: ='เมือง'!D23+'ป่าโมก'!D23+'โพธิ์ทอง'!D23+'วิเศษ'!D23+'สามโก้'!D23+'แสวงหา'!D23+'ไชโย'!D23 -> 0 | E23: ='เมือง'!E23+'ป่าโมก'!E23+'โพธิ์ทอง'!E23+'วิเศษ'!E23+'สามโก้'!E23+'แสวงหา'!E23+'ไชโย'!E23 -> 0 | F23: ='เมือง'!F23+'ป่าโมก'!F23+'โพธิ์ทอง'!F23+'วิเศษ'!F23+'สามโก้'!F23+'แสวงหา'!F23+'ไชโย'!F23 -> 0 | G23: ='เมือง'!G23+'ป่าโมก'!G23+'โพธิ์ทอง'!G23+'วิเศษ'!G23+'สามโก้'!G23+'แสวงหา'!G23+'ไชโย'!G23 -> 0 | H23: ='เมือง'!H23+'ป่าโมก'!H23+'โพธิ์ทอง'!H23+'วิเศษ'!H23+'สามโก้'!H23+'แสวงหา'!H23+'ไชโย'!H23 -> 0 | I23: ='เมือง'!I23+'ป่าโมก'!I23+'โพธิ์ทอง'!I23+'วิเศษ'!I23+'สามโก้'!I23+'แสวงหา'!I23+'ไชโย'!I23 -> 0 | ... AP23: ='เมือง'!AP23+'ป่าโมก'!AP23+'โพธิ์ทอง'!AP23+'วิเศษ'!AP23+'สามโก้'!AP23+'แสวงหา'!AP23+'ไชโย'!AP23 -> 0
A24: 25480 | B24: ='เมือง'!B24+'ป่าโมก'!B24+'โพธิ์ทอง'!B24+'วิเศษ'!B24+'สามโก้'!B24+'แสวงหา'!B24+'ไชโย'!B24 -> 0 | C24: ='เมือง'!C24+'ป่าโมก'!C24+'โพธิ์ทอง'!C24+'วิเศษ'!C24+'สามโก้'!C24+'แสวงหา'!C24+'ไชโย'!C24 -> 0 | D24: ='เมือง'!D24+'ป่าโมก'!D24+'โพธิ์ทอง'!D24+'วิเศษ'!D24+'สามโก้'!D24+'แสวงหา'!D24+'ไชโย'!D24 -> 0 | E24: ='เมือง'!E24+'ป่าโมก'!E24+'โพธิ์ทอง'!E24+'วิเศษ'!E24+'สามโก้'!E24+'แสวงหา'!E24+'ไชโย'!E24 -> 0 | F24: ='เมือง'!F24+'ป่าโมก'!F24+'โพธิ์ทอง'!F24+'วิเศษ'!F24+'สามโก้'!F24+'แสวงหา'!F24+'ไชโย'!F24 -> 0 | G24: ='เมือง'!G24+'ป่าโมก'!G24+'โพธิ์ทอง'!G24+'วิเศษ'!G24+'สามโก้'!G24+'แสวงหา'!G24+'ไชโย'!G24 -> 0 | H24: ='เมือง'!H24+'ป่าโมก'!H24+'โพธิ์ทอง'!H24+'วิเศษ'!H24+'สามโก้'!H24+'แสวงหา'!H24+'ไชโย'!H24 -> 0 | I24: ='เมือง'!I24+'ป่าโมก'!I24+'โพธิ์ทอง'!I24+'วิเศษ'!I24+'สามโก้'!I24+'แสวงหา'!I24+'ไชโย'!I24 -> 0 | ... AP24: ='เมือง'!AP24+'ป่าโมก'!AP24+'โพธิ์ทอง'!AP24+'วิเศษ'!AP24+'สามโก้'!AP24+'แสวงหา'!AP24+'ไชโย'!AP24 -> 0
A25: 25481 | B25: ='เมือง'!B25+'ป่าโมก'!B25+'โพธิ์ทอง'!B25+'วิเศษ'!B25+'สามโก้'!B25+'แสวงหา'!B25+'ไชโย'!B25 -> 0 | C25: ='เมือง'!C25+'ป่าโมก'!C25+'โพธิ์ทอง'!C25+'วิเศษ'!C25+'สามโก้'!C25+'แสวงหา'!C25+'ไชโย'!C25 -> 0 | D25: ='เมือง'!D25+'ป่าโมก'!D25+'โพธิ์ทอง'!D25+'วิเศษ'!D25+'สามโก้'!D25+'แสวงหา'!D25+'ไชโย'!D25 -> 0 | E25: ='เมือง'!E25+'ป่าโมก'!E25+'โพธิ์ทอง'!E25+'วิเศษ'!E25+'สามโก้'!E25+'แสวงหา'!E25+'ไชโย'!E25 -> 0 | F25: ='เมือง'!F25+'ป่าโมก'!F25+'โพธิ์ทอง'!F25+'วิเศษ'!F25+'สามโก้'!F25+'แสวงหา'!F25+'ไชโย'!F25 -> 0 | G25: ='เมือง'!G25+'ป่าโมก'!G25+'โพธิ์ทอง'!G25+'วิเศษ'!G25+'สามโก้'!G25+'แสวงหา'!G25+'ไชโย'!G25 -> 0 | H25: ='เมือง'!H25+'ป่าโมก'!H25+'โพธิ์ทอง'!H25+'วิเศษ'!H25+'สามโก้'!H25+'แสวงหา'!H25+'ไชโย'!H25 -> 0 | I25: ='เมือง'!I25+'ป่าโมก'!I25+'โพธิ์ทอง'!I25+'วิเศษ'!I25+'สามโก้'!I25+'แสวงหา'!I25+'ไชโย'!I25 -> 0 | ... AP25: ='เมือง'!AP25+'ป่าโมก'!AP25+'โพธิ์ทอง'!AP25+'วิเศษ'!AP25+'สามโก้'!AP25+'แสวงหา'!AP25+'ไชโย'!AP25 -> 0
A26: 25482 | B26: ='เมือง'!B26+'ป่าโมก'!B26+'โพธิ์ทอง'!B26+'วิเศษ'!B26+'สามโก้'!B26+'แสวงหา'!B26+'ไชโย'!B26 -> 0 | C26: ='เมือง'!C26+'ป่าโมก'!C26+'โพธิ์ทอง'!C26+'วิเศษ'!C26+'สามโก้'!C26+'แสวงหา'!C26+'ไชโย'!C26 -> 0 | D26: ='เมือง'!D26+'ป่าโมก'!D26+'โพธิ์ทอง'!D26+'วิเศษ'!D26+'สามโก้'!D26+'แสวงหา'!D26+'ไชโย'!D26 -> 0 | E26: ='เมือง'!E26+'ป่าโมก'!E26+'โพธิ์ทอง'!E26+'วิเศษ'!E26+'สามโก้'!E26+'แสวงหา'!E26+'ไชโย'!E26 -> 0 | F26: ='เมือง'!F26+'ป่าโมก'!F26+'โพธิ์ทอง'!F26+'วิเศษ'!F26+'สามโก้'!F26+'แสวงหา'!F26+'ไชโย'!F26 -> 0 | G26: ='เมือง'!G26+'ป่าโมก'!G26+'โพธิ์ทอง'!G26+'วิเศษ'!G26+'สามโก้'!G26+'แสวงหา'!G26+'ไชโย'!G26 -> 0 | H26: ='เมือง'!H26+'ป่าโมก'!H26+'โพธิ์ทอง'!H26+'วิเศษ'!H26+'สามโก้'!H26+'แสวงหา'!H26+'ไชโย'!H26 -> 0 | I26: ='เมือง'!I26+'ป่าโมก'!I26+'โพธิ์ทอง'!I26+'วิเศษ'!I26+'สามโก้'!I26+'แสวงหา'!I26+'ไชโย'!I26 -> 0 | ... AP26: ='เมือง'!AP26+'ป่าโมก'!AP26+'โพธิ์ทอง'!AP26+'วิเศษ'!AP26+'สามโก้'!AP26+'แสวงหา'!AP26+'ไชโย'!AP26 -> 0
A27: 25483 | B27: ='เมือง'!B27+'ป่าโมก'!B27+'โพธิ์ทอง'!B27+'วิเศษ'!B27+'สามโก้'!B27+'แสวงหา'!B27+'ไชโย'!B27 -> 0 | C27: ='เมือง'!C27+'ป่าโมก'!C27+'โพธิ์ทอง'!C27+'วิเศษ'!C27+'สามโก้'!C27+'แสวงหา'!C27+'ไชโย'!C27 -> 0 | D27: ='เมือง'!D27+'ป่าโมก'!D27+'โพธิ์ทอง'!D27+'วิเศษ'!D27+'สามโก้'!D27+'แสวงหา'!D27+'ไชโย'!D27 -> 0 | E27: ='เมือง'!E27+'ป่าโมก'!E27+'โพธิ์ทอง'!E27+'วิเศษ'!E27+'สามโก้'!E27+'แสวงหา'!E27+'ไชโย'!E27 -> 0 | F27: ='เมือง'!F27+'ป่าโมก'!F27+'โพธิ์ทอง'!F27+'วิเศษ'!F27+'สามโก้'!F27+'แสวงหา'!F27+'ไชโย'!F27 -> 0 | G27: ='เมือง'!G27+'ป่าโมก'!G27+'โพธิ์ทอง'!G27+'วิเศษ'!G27+'สามโก้'!G27+'แสวงหา'!G27+'ไชโย'!G27 -> 0 | H27: ='เมือง'!H27+'ป่าโมก'!H27+'โพธิ์ทอง'!H27+'วิเศษ'!H27+'สามโก้'!H27+'แสวงหา'!H27+'ไชโย'!H27 -> 0 | I27: ='เมือง'!I27+'ป่าโมก'!I27+'โพธิ์ทอง'!I27+'วิเศษ'!I27+'สามโก้'!I27+'แสวงหา'!I27+'ไชโย'!I27 -> 0 | ... AP27: ='เมือง'!AP27+'ป่าโมก'!AP27+'โพธิ์ทอง'!AP27+'วิเศษ'!AP27+'สามโก้'!AP27+'แสวงหา'!AP27+'ไชโย'!AP27 -> 0
A28: 25484 | B28: ='เมือง'!B28+'ป่าโมก'!B28+'โพธิ์ทอง'!B28+'วิเศษ'!B28+'สามโก้'!B28+'แสวงหา'!B28+'ไชโย'!B28 -> 0 | C28: ='เมือง'!C28+'ป่าโมก'!C28+'โพธิ์ทอง'!C28+'วิเศษ'!C28+'สามโก้'!C28+'แสวงหา'!C28+'ไชโย'!C28 -> 0 | D28: ='เมือง'!D28+'ป่าโมก'!D28+'โพธิ์ทอง'!D28+'วิเศษ'!D28+'สามโก้'!D28+'แสวงหา'!D28+'ไชโย'!D28 -> 0 | E28: ='เมือง'!E28+'ป่าโมก'!E28+'โพธิ์ทอง'!E28+'วิเศษ'!E28+'สามโก้'!E28+'แสวงหา'!E28+'ไชโย'!E28 -> 0 | F28: ='เมือง'!F28+'ป่าโมก'!F28+'โพธิ์ทอง'!F28+'วิเศษ'!F28+'สามโก้'!F28+'แสวงหา'!F28+'ไชโย'!F28 -> 0 | G28: ='เมือง'!G28+'ป่าโมก'!G28+'โพธิ์ทอง'!G28+'วิเศษ'!G28+'สามโก้'!G28+'แสวงหา'!G28+'ไชโย'!G28 -> 0 | H28: ='เมือง'!H28+'ป่าโมก'!H28+'โพธิ์ทอง'!H28+'วิเศษ'!H28+'สามโก้'!H28+'แสวงหา'!H28+'ไชโย'!H28 -> 0 | I28: ='เมือง'!I28+'ป่าโมก'!I28+'โพธิ์ทอง'!I28+'วิเศษ'!I28+'สามโก้'!I28+'แสวงหา'!I28+'ไชโย'!I28 -> 0 | ... AP28: ='เมือง'!AP28+'ป่าโมก'!AP28+'โพธิ์ทอง'!AP28+'วิเศษ'!AP28+'สามโก้'!AP28+'แสวงหา'!AP28+'ไชโย'!AP28 -> 0
A29: 25485 | B29: ='เมือง'!B29+'ป่าโมก'!B29+'โพธิ์ทอง'!B29+'วิเศษ'!B29+'สามโก้'!B29+'แสวงหา'!B29+'ไชโย'!B29 -> 0 | C29: ='เมือง'!C29+'ป่าโมก'!C29+'โพธิ์ทอง'!C29+'วิเศษ'!C29+'สามโก้'!C29+'แสวงหา'!C29+'ไชโย'!C29 -> 0 | D29: ='เมือง'!D29+'ป่าโมก'!D29+'โพธิ์ทอง'!D29+'วิเศษ'!D29+'สามโก้'!D29+'แสวงหา'!D29+'ไชโย'!D29 -> 0 | E29: ='เมือง'!E29+'ป่าโมก'!E29+'โพธิ์ทอง'!E29+'วิเศษ'!E29+'สามโก้'!E29+'แสวงหา'!E29+'ไชโย'!E29 -> 0 | F29: ='เมือง'!F29+'ป่าโมก'!F29+'โพธิ์ทอง'!F29+'วิเศษ'!F29+'สามโก้'!F29+'แสวงหา'!F29+'ไชโย'!F29 -> 0 | G29: ='เมือง'!G29+'ป่าโมก'!G29+'โพธิ์ทอง'!G29+'วิเศษ'!G29+'สามโก้'!G29+'แสวงหา'!G29+'ไชโย'!G29 -> 0 | H29: ='เมือง'!H29+'ป่าโมก'!H29+'โพธิ์ทอง'!H29+'วิเศษ'!H29+'สามโก้'!H29+'แสวงหา'!H29+'ไชโย'!H29 -> 0 | I29: ='เมือง'!I29+'ป่าโมก'!I29+'โพธิ์ทอง'!I29+'วิเศษ'!I29+'สามโก้'!I29+'แสวงหา'!I29+'ไชโย'!I29 -> 0 | ... AP29: ='เมือง'!AP29+'ป่าโมก'!AP29+'โพธิ์ทอง'!AP29+'วิเศษ'!AP29+'สามโก้'!AP29+'แสวงหา'!AP29+'ไชโย'!AP29 -> 0
A30: 25486 | B30: ='เมือง'!B30+'ป่าโมก'!B30+'โพธิ์ทอง'!B30+'วิเศษ'!B30+'สามโก้'!B30+'แสวงหา'!B30+'ไชโย'!B30 -> 0 | C30: ='เมือง'!C30+'ป่าโมก'!C30+'โพธิ์ทอง'!C30+'วิเศษ'!C30+'สามโก้'!C30+'แสวงหา'!C30+'ไชโย'!C30 -> 0 | D30: ='เมือง'!D30+'ป่าโมก'!D30+'โพธิ์ทอง'!D30+'วิเศษ'!D30+'สามโก้'!D30+'แสวงหา'!D30+'ไชโย'!D30 -> 0 | E30: ='เมือง'!E30+'ป่าโมก'!E30+'โพธิ์ทอง'!E30+'วิเศษ'!E30+'สามโก้'!E30+'แสวงหา'!E30+'ไชโย'!E30 -> 0 | F30: ='เมือง'!F30+'ป่าโมก'!F30+'โพธิ์ทอง'!F30+'วิเศษ'!F30+'สามโก้'!F30+'แสวงหา'!F30+'ไชโย'!F30 -> 0 | G30: ='เมือง'!G30+'ป่าโมก'!G30+'โพธิ์ทอง'!G30+'วิเศษ'!G30+'สามโก้'!G30+'แสวงหา'!G30+'ไชโย'!G30 -> 0 | H30: ='เมือง'!H30+'ป่าโมก'!H30+'โพธิ์ทอง'!H30+'วิเศษ'!H30+'สามโก้'!H30+'แสวงหา'!H30+'ไชโย'!H30 -> 0 | I30: ='เมือง'!I30+'ป่าโมก'!I30+'โพธิ์ทอง'!I30+'วิเศษ'!I30+'สามโก้'!I30+'แสวงหา'!I30+'ไชโย'!I30 -> 0 | ... AP30: ='เมือง'!AP30+'ป่าโมก'!AP30+'โพธิ์ทอง'!AP30+'วิเศษ'!AP30+'สามโก้'!AP30+'แสวงหา'!AP30+'ไชโย'!AP30 -> 0
A31: 25487 | B31: ='เมือง'!B31+'ป่าโมก'!B31+'โพธิ์ทอง'!B31+'วิเศษ'!B31+'สามโก้'!B31+'แสวงหา'!B31+'ไชโย'!B31 -> 0 | C31: ='เมือง'!C31+'ป่าโมก'!C31+'โพธิ์ทอง'!C31+'วิเศษ'!C31+'สามโก้'!C31+'แสวงหา'!C31+'ไชโย'!C31 -> 0 | D31: ='เมือง'!D31+'ป่าโมก'!D31+'โพธิ์ทอง'!D31+'วิเศษ'!D31+'สามโก้'!D31+'แสวงหา'!D31+'ไชโย'!D31 -> 0 | E31: ='เมือง'!E31+'ป่าโมก'!E31+'โพธิ์ทอง'!E31+'วิเศษ'!E31+'สามโก้'!E31+'แสวงหา'!E31+'ไชโย'!E31 -> 0 | F31: ='เมือง'!F31+'ป่าโมก'!F31+'โพธิ์ทอง'!F31+'วิเศษ'!F31+'สามโก้'!F31+'แสวงหา'!F31+'ไชโย'!F31 -> 0 | G31: ='เมือง'!G31+'ป่าโมก'!G31+'โพธิ์ทอง'!G31+'วิเศษ'!G31+'สามโก้'!G31+'แสวงหา'!G31+'ไชโย'!G31 -> 0 | H31: ='เมือง'!H31+'ป่าโมก'!H31+'โพธิ์ทอง'!H31+'วิเศษ'!H31+'สามโก้'!H31+'แสวงหา'!H31+'ไชโย'!H31 -> 0 | I31: ='เมือง'!I31+'ป่าโมก'!I31+'โพธิ์ทอง'!I31+'วิเศษ'!I31+'สามโก้'!I31+'แสวงหา'!I31+'ไชโย'!I31 -> 0 | ... AP31: ='เมือง'!AP31+'ป่าโมก'!AP31+'โพธิ์ทอง'!AP31+'วิเศษ'!AP31+'สามโก้'!AP31+'แสวงหา'!AP31+'ไชโย'!AP31 -> 0
... A52: 25508 | B52: ='เมือง'!B52+'ป่าโมก'!B52+'โพธิ์ทอง'!B52+'วิเศษ'!B52+'สามโก้'!B52+'แสวงหา'!B52+'ไชโย'!B52 -> 0 | C52: ='เมือง'!C52+'ป่าโมก'!C52+'โพธิ์ทอง'!C52+'วิเศษ'!C52+'สามโก้'!C52+'แสวงหา'!C52+'ไชโย'!C52 -> 0 | D52: ='เมือง'!D52+'ป่าโมก'!D52+'โพธิ์ทอง'!D52+'วิเศษ'!D52+'สามโก้'!D52+'แสวงหา'!D52+'ไชโย'!D52 -> 0 | E52: ='เมือง'!E52+'ป่าโมก'!E52+'โพธิ์ทอง'!E52+'วิเศษ'!E52+'สามโก้'!E52+'แสวงหา'!E52+'ไชโย'!E52 -> 0 | F52: ='เมือง'!F52+'ป่าโมก'!F52+'โพธิ์ทอง'!F52+'วิเศษ'!F52+'สามโก้'!F52+'แสวงหา'!F52+'ไชโย'!F52 -> 0 | G52: ='เมือง'!G52+'ป่าโมก'!G52+'โพธิ์ทอง'!G52+'วิเศษ'!G52+'สามโก้'!G52+'แสวงหา'!G52+'ไชโย'!G52 -> 0 | H52: ='เมือง'!H52+'ป่าโมก'!H52+'โพธิ์ทอง'!H52+'วิเศษ'!H52+'สามโก้'!H52+'แสวงหา'!H52+'ไชโย'!H52 -> 0 | I52: ='เมือง'!I52+'ป่าโมก'!I52+'โพธิ์ทอง'!I52+'วิเศษ'!I52+'สามโก้'!I52+'แสวงหา'!I52+'ไชโย'!I52 -> 0 | ... AP52: ='เมือง'!AP52+'ป่าโมก'!AP52+'โพธิ์ทอง'!AP52+'วิเศษ'!AP52+'สามโก้'!AP52+'แสวงหา'!AP52+'ไชโย'!AP52 -> 0
AP53: ='เมือง'!AP53+'ไชโย'!AP53+'ป่าโมก'!AP53+'โพธิ์ทอง'!AP53+'วิเศษ'!AP53+'สามโก้'!AP53+'แสวงหา'!AP53 -> 0
A56: 3. การให้บริการด้านการแพทย์และสาธารณสุข ** สถานบริการบันทึก **
A58: สถานที่ออกหน่วย | B58: หมู่ที่ | C58: ชื่อหมู่บ้าน/ชุมชน | D58: จำนวนประชาชน ที่เข้ารับบริการ (คน) | E58: ทีมปฏิบัติการ | I58: การให้บริการด้านการแพทย์และสาธารณสุข (ราย) | P58: คัดกรองสุขภาพจิต (ราย) | V58: โรคที่พบบ่อยจากการออกหน่วยแพทย์เคลื่อนที่ (ราย) | AI58: อุบัติเหตุทางน้ำ | AK58: การสนับสนุนทรัพยากรให้แก่ประชาชน | AV58: จำนวน ศูนย์พักพิง (แห่ง) | AW58: ชื่อ-สกุลผู้รายงาน | AX58: เบอร์โทร
E59: หน่วยแพทย์เคลื่อนที่ | F59: MCATT | G59: SRRT | H59: ShERT
E60: จำนวน (ครั้ง) | F60: จำนวน (ครั้ง) | G60: จำนวน (ครั้ง) | H60: จำนวน (ครั้ง) | I60: จัดส่งยาโรคประจำตัว | J60: เยี่ยมบ้าน | K60: รับยา/แจกยา | L60: ให้บริการสุขศึกษา | M60: ตรวจรักษา | N60: การส่งต่อ | O60: อื่นๆ | P60: จำนวนผู้เข้ารับการคัดกรอง | Q60: เครียดสูง | R60: เสี่ยงซึมเศร้า | S60: เสี่ยงต่อการฆ่าตัวตาย | T60: การให้ความช่วยเหลือ | V60: 1. โรคระบบทางเดินหายใจ | W60: 2. โรคระบบทางเดินอาหาร | X60: 3. โรคระบบไหลเวียนโลหิต | Y60: 4. โรคตาอักเสบ/ตาแดง | Z60: 5. โรคผิวหนัง เช่น แพ้ ผื่นคัน | AA60: 6. โรคน้ำกัดเท้า | AB60: 7. ปวดเมื่อยกล้ามเนื้อ | AC60: 8. ปวดศรีษะ เวียนศรีษะ | AD60: 9. ไข้เลือดออก | AE60: 10. อุจจาระร่วงเฉียบพลัน/อาหารเป็นพิษ | AF60: 11. เหนื่อย อ่อนเพลีย | AG60: 12. โรคที่เกิดจากการติดเชื้อไวรัส | AH60: 13. อื่นๆ ระบุ | AI60: จมน้ำ (ราย) | AJ60: ไฟช๊อต (ราย) | AK60: ยาชุดช่วยเหลือผู้ประสบภัย (ชุด) | AL60: ยาสามัญประจำบ้าน (ชุด) | AM60: ยารักษาน้ำกัดเท้า (หลอด) | AN60: ยาทากลากเกลื่อน (ชุด) | AO60: รองเท้าบูท (คู่) | AP60: ยากันยุง (ซอง) | AQ60: ถุงดำ | AR60: สารส้ม | AS60: คลอรีน | AT60: EM | AU60: อื่นๆ
T61: ปฐมพยาบาลทางใจ (PFA) | U61: พบแพทย์
A62: 25475 | D62: ='เมือง'!D62+'ป่าโมก'!D62+'โพธิ์ทอง'!D62+'วิเศษ'!D62+'สามโก้'!D62+'แสวงหา'!D62+'ไชโย'!D62 -> 0 | E62: ='เมือง'!E62+'ป่าโมก'!E62+'โพธิ์ทอง'!E62+'วิเศษ'!E62+'สามโก้'!E62+'แสวงหา'!E62+'ไชโย'!E62 -> 0 | F62: ='เมือง'!F62+'ป่าโมก'!F62+'โพธิ์ทอง'!F62+'วิเศษ'!F62+'สามโก้'!F62+'แสวงหา'!F62+'ไชโย'!F62 -> 0 | G62: ='เมือง'!G62+'ป่าโมก'!G62+'โพธิ์ทอง'!G62+'วิเศษ'!G62+'สามโก้'!G62+'แสวงหา'!G62+'ไชโย'!G62 -> 0 | H62: ='เมือง'!H62+'ป่าโมก'!H62+'โพธิ์ทอง'!H62+'วิเศษ'!H62+'สามโก้'!H62+'แสวงหา'!H62+'ไชโย'!H62 -> 0 | I62: ='เมือง'!I62+'ป่าโมก'!I62+'โพธิ์ทอง'!I62+'วิเศษ'!I62+'สามโก้'!I62+'แสวงหา'!I62+'ไชโย'!I62 -> 0 | J62: ='เมือง'!J62+'ป่าโมก'!J62+'โพธิ์ทอง'!J62+'วิเศษ'!J62+'สามโก้'!J62+'แสวงหา'!J62+'ไชโย'!J62 -> 252 | K62: ='เมือง'!K62+'ป่าโมก'!K62+'โพธิ์ทอง'!K62+'วิเศษ'!K62+'สามโก้'!K62+'แสวงหา'!K62+'ไชโย'!K62 -> 222 | ... AX62: ='เมือง'!AX62+'ป่าโมก'!AX62+'โพธิ์ทอง'!AX62+'วิเศษ'!AX62+'สามโก้'!AX62+'แสวงหา'!AX62+'ไชโย'!AX62 -> 0
A63: 25476 | D63: ='เมือง'!D63+'ป่าโมก'!D63+'โพธิ์ทอง'!D63+'วิเศษ'!D63+'สามโก้'!D63+'แสวงหา'!D63+'ไชโย'!D63 -> 306 | E63: ='เมือง'!E63+'ป่าโมก'!E63+'โพธิ์ทอง'!E63+'วิเศษ'!E63+'สามโก้'!E63+'แสวงหา'!E63+'ไชโย'!E63 -> 0 | F63: ='เมือง'!F63+'ป่าโมก'!F63+'โพธิ์ทอง'!F63+'วิเศษ'!F63+'สามโก้'!F63+'แสวงหา'!F63+'ไชโย'!F63 -> 33 | G63: ='เมือง'!G63+'ป่าโมก'!G63+'โพธิ์ทอง'!G63+'วิเศษ'!G63+'สามโก้'!G63+'แสวงหา'!G63+'ไชโย'!G63 -> 7 | H63: ='เมือง'!H63+'ป่าโมก'!H63+'โพธิ์ทอง'!H63+'วิเศษ'!H63+'สามโก้'!H63+'แสวงหา'!H63+'ไชโย'!H63 -> 0 | I63: ='เมือง'!I63+'ป่าโมก'!I63+'โพธิ์ทอง'!I63+'วิเศษ'!I63+'สามโก้'!I63+'แสวงหา'!I63+'ไชโย'!I63 -> 47 | J63: ='เมือง'!J63+'ป่าโมก'!J63+'โพธิ์ทอง'!J63+'วิเศษ'!J63+'สามโก้'!J63+'แสวงหา'!J63+'ไชโย'!J63 -> 218 | K63: ='เมือง'!K63+'ป่าโมก'!K63+'โพธิ์ทอง'!K63+'วิเศษ'!K63+'สามโก้'!K63+'แสวงหา'!K63+'ไชโย'!K63 -> 215 | ... AX63: ='เมือง'!AX63+'ป่าโมก'!AX63+'โพธิ์ทอง'!AX63+'วิเศษ'!AX63+'สามโก้'!AX63+'แสวงหา'!AX63+'ไชโย'!AX63 -> 0
A64: 25477 | D64: ='เมือง'!D64+'ป่าโมก'!D64+'โพธิ์ทอง'!D64+'วิเศษ'!D64+'สามโก้'!D64+'แสวงหา'!D64+'ไชโย'!D64 -> 104 | E64: ='เมือง'!E64+'ป่าโมก'!E64+'โพธิ์ทอง'!E64+'วิเศษ'!E64+'สามโก้'!E64+'แสวงหา'!E64+'ไชโย'!E64 -> 2 | F64: ='เมือง'!F64+'ป่าโมก'!F64+'โพธิ์ทอง'!F64+'วิเศษ'!F64+'สามโก้'!F64+'แสวงหา'!F64+'ไชโย'!F64 -> 52 | G64: ='เมือง'!G64+'ป่าโมก'!G64+'โพธิ์ทอง'!G64+'วิเศษ'!G64+'สามโก้'!G64+'แสวงหา'!G64+'ไชโย'!G64 -> 7 | H64: ='เมือง'!H64+'ป่าโมก'!H64+'โพธิ์ทอง'!H64+'วิเศษ'!H64+'สามโก้'!H64+'แสวงหา'!H64+'ไชโย'!H64 -> 5 | I64: ='เมือง'!I64+'ป่าโมก'!I64+'โพธิ์ทอง'!I64+'วิเศษ'!I64+'สามโก้'!I64+'แสวงหา'!I64+'ไชโย'!I64 -> 23 | J64: ='เมือง'!J64+'ป่าโมก'!J64+'โพธิ์ทอง'!J64+'วิเศษ'!J64+'สามโก้'!J64+'แสวงหา'!J64+'ไชโย'!J64 -> 114 | K64: ='เมือง'!K64+'ป่าโมก'!K64+'โพธิ์ทอง'!K64+'วิเศษ'!K64+'สามโก้'!K64+'แสวงหา'!K64+'ไชโย'!K64 -> 71 | ... AX64: ='เมือง'!AX64+'ป่าโมก'!AX64+'โพธิ์ทอง'!AX64+'วิเศษ'!AX64+'สามโก้'!AX64+'แสวงหา'!AX64+'ไชโย'!AX64 -> 0
A65: 25478 | D65: ='เมือง'!D65+'ป่าโมก'!D65+'โพธิ์ทอง'!D65+'วิเศษ'!D65+'สามโก้'!D65+'แสวงหา'!D65+'ไชโย'!D65 -> 32 | E65: ='เมือง'!E65+'ป่าโมก'!E65+'โพธิ์ทอง'!E65+'วิเศษ'!E65+'สามโก้'!E65+'แสวงหา'!E65+'ไชโย'!E65 -> 0 | F65: ='เมือง'!F65+'ป่าโมก'!F65+'โพธิ์ทอง'!F65+'วิเศษ'!F65+'สามโก้'!F65+'แสวงหา'!F65+'ไชโย'!F65 -> 0 | G65: ='เมือง'!G65+'ป่าโมก'!G65+'โพธิ์ทอง'!G65+'วิเศษ'!G65+'สามโก้'!G65+'แสวงหา'!G65+'ไชโย'!G65 -> 3 | H65: ='เมือง'!H65+'ป่าโมก'!H65+'โพธิ์ทอง'!H65+'วิเศษ'!H65+'สามโก้'!H65+'แสวงหา'!H65+'ไชโย'!H65 -> 0 | I65: ='เมือง'!I65+'ป่าโมก'!I65+'โพธิ์ทอง'!I65+'วิเศษ'!I65+'สามโก้'!I65+'แสวงหา'!I65+'ไชโย'!I65 -> 0 | J65: ='เมือง'!J65+'ป่าโมก'!J65+'โพธิ์ทอง'!J65+'วิเศษ'!J65+'สามโก้'!J65+'แสวงหา'!J65+'ไชโย'!J65 -> 3 | K65: ='เมือง'!K65+'ป่าโมก'!K65+'โพธิ์ทอง'!K65+'วิเศษ'!K65+'สามโก้'!K65+'แสวงหา'!K65+'ไชโย'!K65 -> 26 | ... AX65: ='เมือง'!AX65+'ป่าโมก'!AX65+'โพธิ์ทอง'!AX65+'วิเศษ'!AX65+'สามโก้'!AX65+'แสวงหา'!AX65+'ไชโย'!AX65 -> 0
A66: 25479 | D66: ='เมือง'!D66+'ป่าโมก'!D66+'โพธิ์ทอง'!D66+'วิเศษ'!D66+'สามโก้'!D66+'แสวงหา'!D66+'ไชโย'!D66 -> 0 | E66: ='เมือง'!E66+'ป่าโมก'!E66+'โพธิ์ทอง'!E66+'วิเศษ'!E66+'สามโก้'!E66+'แสวงหา'!E66+'ไชโย'!E66 -> 0 | F66: ='เมือง'!F66+'ป่าโมก'!F66+'โพธิ์ทอง'!F66+'วิเศษ'!F66+'สามโก้'!F66+'แสวงหา'!F66+'ไชโย'!F66 -> 0 | G66: ='เมือง'!G66+'ป่าโมก'!G66+'โพธิ์ทอง'!G66+'วิเศษ'!G66+'สามโก้'!G66+'แสวงหา'!G66+'ไชโย'!G66 -> 0 | H66: ='เมือง'!H66+'ป่าโมก'!H66+'โพธิ์ทอง'!H66+'วิเศษ'!H66+'สามโก้'!H66+'แสวงหา'!H66+'ไชโย'!H66 -> 0 | I66: ='เมือง'!I66+'ป่าโมก'!I66+'โพธิ์ทอง'!I66+'วิเศษ'!I66+'สามโก้'!I66+'แสวงหา'!I66+'ไชโย'!I66 -> 0 | J66: ='เมือง'!J66+'ป่าโมก'!J66+'โพธิ์ทอง'!J66+'วิเศษ'!J66+'สามโก้'!J66+'แสวงหา'!J66+'ไชโย'!J66 -> 0 | K66: ='เมือง'!K66+'ป่าโมก'!K66+'โพธิ์ทอง'!K66+'วิเศษ'!K66+'สามโก้'!K66+'แสวงหา'!K66+'ไชโย'!K66 -> 0 | ... AX66: ='เมือง'!AX66+'ป่าโมก'!AX66+'โพธิ์ทอง'!AX66+'วิเศษ'!AX66+'สามโก้'!AX66+'แสวงหา'!AX66+'ไชโย'!AX66 -> 0
A67: 25480 | D67: ='เมือง'!D67+'ป่าโมก'!D67+'โพธิ์ทอง'!D67+'วิเศษ'!D67+'สามโก้'!D67+'แสวงหา'!D67+'ไชโย'!D67 -> 0 | E67: ='เมือง'!E67+'ป่าโมก'!E67+'โพธิ์ทอง'!E67+'วิเศษ'!E67+'สามโก้'!E67+'แสวงหา'!E67+'ไชโย'!E67 -> 0 | F67: ='เมือง'!F67+'ป่าโมก'!F67+'โพธิ์ทอง'!F67+'วิเศษ'!F67+'สามโก้'!F67+'แสวงหา'!F67+'ไชโย'!F67 -> 0 | G67: ='เมือง'!G67+'ป่าโมก'!G67+'โพธิ์ทอง'!G67+'วิเศษ'!G67+'สามโก้'!G67+'แสวงหา'!G67+'ไชโย'!G67 -> 0 | H67: ='เมือง'!H67+'ป่าโมก'!H67+'โพธิ์ทอง'!H67+'วิเศษ'!H67+'สามโก้'!H67+'แสวงหา'!H67+'ไชโย'!H67 -> 0 | I67: ='เมือง'!I67+'ป่าโมก'!I67+'โพธิ์ทอง'!I67+'วิเศษ'!I67+'สามโก้'!I67+'แสวงหา'!I67+'ไชโย'!I67 -> 0 | J67: ='เมือง'!J67+'ป่าโมก'!J67+'โพธิ์ทอง'!J67+'วิเศษ'!J67+'สามโก้'!J67+'แสวงหา'!J67+'ไชโย'!J67 -> 0 | K67: ='เมือง'!K67+'ป่าโมก'!K67+'โพธิ์ทอง'!K67+'วิเศษ'!K67+'สามโก้'!K67+'แสวงหา'!K67+'ไชโย'!K67 -> 0 | ... AX67: ='เมือง'!AX67+'ป่าโมก'!AX67+'โพธิ์ทอง'!AX67+'วิเศษ'!AX67+'สามโก้'!AX67+'แสวงหา'!AX67+'ไชโย'!AX67 -> 0
...

Sheet onepage1ตค
B2: การดูแลกลุ่มเปราะบาง | C2: ข้อมูลปัจจุบัน | F2: จำนวนกลุ่มเปราะบางที่ได้รับผลกระทบ | I2: ทีมปฏิบัติการ
B3: จำนวนกลุ่มเปราะบางที่ได้รับผลกระทบ ยอดยกมา
B4: ผู้สูงอายุ | C4: 397 | F4: ผู้ป่วยติดเตียง | G4: 111 | I4: หน่วยแพทย์เคลื่อนที่ | J4: ='รวมตาราง จ.อ่างทอง'!E96 -> 2
B5: ผู้ป่วยโรคเรื้อรัง (NCD) | C5: 253 | F5: ผู้ป่วยฟอกไต | G5: ='รวมตาราง จ.อ่างทอง'!H21 -> 1 | I5: MCATT | J5: 20
B6: ผู้ป่วยฟอกไต | C6: 2 | F6: จิตเวช (ที่ต้องรับยา) | G6: ='รวมตาราง จ.อ่างทอง'!M21 -> 21 | I6: SRRT | J6: ='รวมตาราง จ.อ่างทอง'!G96 -> 17
B7: ผู้ป่วยติดเตียง | C7: 24 | F7: ผู้สูงอายุ | G7: ='รวมตาราง จ.อ่างทอง'!R21 -> 310 | I7: ShERT | J7: ='รวมตาราง จ.อ่างทอง'!H96 -> 5
B8: ผู้พิการ | C8: 22 | F8: ผู้พิการ
B9: หญิงตั้งครรภ์ | C9: 3 | F9: ผู้ป่วยโรคเรื้อรัง (NCD)
B10: จิตเวช (ที่ต้องรับยา) | C10: 7 | F10: หญิงตั้งครรภ์
B11: เด็กอายุ (0-5 ปี) | C11: 0 | F11: เด็กอายุ (0-5 ปี)
B13: การให้บริการด้านการแพทย์และสาธารณสุข (ราย) | E13: คัดกรองสุขภาพจิต (ราย) | H13: โรคที่พบบ่อยจากการออกหน่วยแพทย์เคลื่อนที่ (ราย) | K13: การสนับสนุนทรัพยากรให้แก่ประชาชน
B14: จัดส่งยาโรคประจำตัว | C14: ='รวมตาราง จ.อ่างทอง'!I96 -> 70 | E14: จำนวนผู้เข้ารับการคัดกรอง | F14: ='รวมตาราง จ.อ่างทอง'!P96 -> 139 | H14: 1. โรคระบบทางเดินหายใจ | I14: ='รวมตาราง จ.อ่างทอง'!V96 -> 0 | K14: ยาชุดช่วยเหลือผู้ประสบภัย (ชุด) | M14: ='รวมตาราง จ.อ่างทอง'!AK96 -> 132
B15: เยี่ยมบ้าน | C15: ='รวมตาราง จ.อ่างทอง'!J96 -> 587 | E15: เครียดสูง | F15: ='รวมตาราง จ.อ่างทอง'!Q96 -> 0 | H15: 2. โรคระบบทางเดินอาหาร | I15: ='รวมตาราง จ.อ่างทอง'!W96 -> 0 | K15: ยาสามัญประจำบ้าน (ชุด) | M15: ='รวมตาราง จ.อ่างทอง'!AL96 -> 23
B16: รับยา/แจกยา | C16: ='รวมตาราง จ.อ่างทอง'!K96 -> 534 | E16: เสี่ยงซึมเศร้า | F16: ='รวมตาราง จ.อ่างทอง'!R96 -> 0 | H16: 3. โรคระบบไหลเวียนโลหิต | I16: ='รวมตาราง จ.อ่างทอง'!X96 -> 0 | K16: ยารักษาน้ำกัดเท้า (หลอด) | M16: ='รวมตาราง จ.อ่างทอง'!AM96 -> 390
B17: ให้บริการสุขศึกษา | C17: ='รวมตาราง จ.อ่างทอง'!L96 -> 595 | E17: เสี่ยงต่อการฆ่าตัวตาย | F17: ='รวมตาราง จ.อ่างทอง'!S96 -> 0 | H17: 4. โรคตาอักเสบ/ตาแดง | I17: ='รวมตาราง จ.อ่างทอง'!Y96 -> 5 | K17: ยาทากลากเกลื่อน (ชุด) | M17: ='รวมตาราง จ.อ่างทอง'!AN96 -> 0
B18: ตรวจรักษา | C18: ='รวมตาราง จ.อ่างทอง'!M96 -> 2 | E18: การให้ความช่วยเหลือ | H18: 5. โรคผิวหนัง เช่น แพ้ ผื่นคัน | I18: ='รวมตาราง จ.อ่างทอง'!Z96 -> 43 | K18: รองเท้าบูท (คู่) | M18: ='รวมตาราง จ.อ่างทอง'!AO96 -> 0
B19: การส่งต่อ | C19: ='รวมตาราง จ.อ่างทอง'!N96 -> 0 | E19: - ปฐมพยาบาลทางใจ (PFA) | F19: ='รวมตาราง จ.อ่างทอง'!T96 -> 28 | H19: 6. โรคน้ำกัดเท้า | I19: ='รวมตาราง จ.อ่างทอง'!AA96 -> 364 | K19: ยากันยุง (ซอง) | M19: ='รวมตาราง จ.อ่างทอง'!AP96 -> 36
B20: อื่นๆ | C20: ='รวมตาราง จ.อ่างทอง'!O96 -> 0 | E20: - พบแพทย์ | F20: ='รวมตาราง จ.อ่างทอง'!U96 -> 0 | H20: 7. ปวดเมื่อยกล้ามเนื้อ | I20: ='รวมตาราง จ.อ่างทอง'!AB96 -> 34 | K20: ถุงดำ | M20: ='รวมตาราง จ.อ่างทอง'!AQ96 -> 67
H21: 8. ปวดศรีษะ เวียนศรีษะ | I21: ='รวมตาราง จ.อ่างทอง'!AC96 -> 10 | K21: สารส้ม | M21: ='รวมตาราง จ.อ่างทอง'!AR96 -> 0
H22: 9. ไข้เลือดออก | I22: ='รวมตาราง จ.อ่างทอง'!AD96 -> 1 | K22: คลอรีน | M22: ='รวมตาราง จ.อ่างทอง'!AS96 -> 0
H23: 10. อุจจาระร่วงเฉียบพลัน/อาหารเป็นพิษ | I23: ='รวมตาราง จ.อ่างทอง'!AE96 -> 0 | K23: EM | M23: ='รวมตาราง จ.อ่างทอง'!AT96 -> 0
H24: 11. เหนื่อย อ่อนเพลีย | I24: ='รวมตาราง จ.อ่างทอง'!AF96 -> 0 | K24: อื่นๆ | M24: ='รวมตาราง จ.อ่างทอง'!AU96 -> 0
H25: 12. โรคที่เกิดจากการติดเชื้อไวรัส | I25: ='รวมตาราง จ.อ่างทอง'!AG96 -> 0
H26: 13. อื่นๆ ระบุ | I26: ='รวมตาราง จ.อ่างทอง'!AH96 -> 0
I28: =SUM(I14:I27) -> 457

Sheet onepage2ตค
B2: การดูแลกลุ่มเปราะบาง | C2: ข้อมูลปัจจุบัน | F2: จำนวนกลุ่มเปราะบางที่ได้รับผลกระทบ | I2: ทีมปฏิบัติการ
B3: จำนวนกลุ่มเปราะบางที่ได้รับผลกระทบ ยอดยกมา
B4: ผู้สูงอายุ | C4: 397 | F4: ผู้ป่วยติดเตียง | G4: 111 | I4: หน่วยแพทย์เคลื่อนที่ | J4: ='รวมตาราง จ.อ่างทอง'!E96 -> 2
B5: ผู้ป่วยโรคเรื้อรัง (NCD) | C5: 253 | F5: ผู้ป่วยฟอกไต | G5: ='รวมตาราง จ.อ่างทอง'!H22 -> 0 | I5: MCATT | J5: ='รวมตาราง จ.อ่างทอง'!F96 -> 85
B6: ผู้ป่วยฟอกไต | C6: 2 | F6: จิตเวช (ที่ต้องรับยา) | G6: ='รวมตาราง จ.อ่างทอง'!M22 -> 0 | I6: SRRT | J6: ='รวมตาราง จ.อ่างทอง'!G96 -> 17
B7: ผู้ป่วยติดเตียง | C7: 24 | F7: ผู้สูงอายุ | G7: ='รวมตาราง จ.อ่างทอง'!R22 -> 31 | I7: ShERT | J7: ='รวมตาราง จ.อ่างทอง'!H96 -> 5
B8: ผู้พิการ | C8: 22 | F8: ผู้พิการ | G8: ='รวมตาราง จ.อ่างทอง'!X22 -> 2
B9: หญิงตั้งครรภ์ | C9: 3 | F9: ผู้ป่วยโรคเรื้อรัง (NCD) | G9: ='รวมตาราง จ.อ่างทอง'!AC22 -> 23
B10: จิตเวช (ที่ต้องรับยา) | C10: 7 | F10: หญิงตั้งครรภ์ | G10: ='รวมตาราง จ.อ่างทอง'!AH22 -> 0
B11: เด็กอายุ (0-5 ปี) | C11: 0 | F11: เด็กอายุ (0-5 ปี) | G11: ='รวมตาราง จ.อ่างทอง'!AM22 -> 3
B13: การให้บริการด้านการแพทย์และสาธารณสุข (ราย) | E13: คัดกรองสุขภาพจิต (ราย) | H13: โรคที่พบบ่อยจากการออกหน่วยแพทย์เคลื่อนที่ (ราย) | K13: การสนับสนุนทรัพยากรให้แก่ประชาชน
B14: จัดส่งยาโรคประจำตัว | C14: ='รวมตาราง จ.อ่างทอง'!I96 -> 70 | E14: จำนวนผู้เข้ารับการคัดกรอง | F14: ='รวมตาราง จ.อ่างทอง'!P96 -> 139 | H14: 1. โรคระบบทางเดินหายใจ | I14: ='รวมตาราง จ.อ่างทอง'!V96 -> 0 | K14: ยาชุดช่วยเหลือผู้ประสบภัย (ชุด) | M14: ='รวมตาราง จ.อ่างทอง'!AK96 -> 132
B15: เยี่ยมบ้าน | C15: ='รวมตาราง จ.อ่างทอง'!J96 -> 587 | E15: เครียดสูง | F15: ='รวมตาราง จ.อ่างทอง'!Q96 -> 0 | H15: 2. โรคระบบทางเดินอาหาร | I15: ='รวมตาราง จ.อ่างทอง'!W96 -> 0 | K15: ยาสามัญประจำบ้าน (ชุด) | M15: ='รวมตาราง จ.อ่างทอง'!AL96 -> 23
B16: รับยา/แจกยา | C16: ='รวมตาราง จ.อ่างทอง'!K96 -> 534 | E16: เสี่ยงซึมเศร้า | F16: ='รวมตาราง จ.อ่างทอง'!R96 -> 0 | H16: 3. โรคระบบไหลเวียนโลหิต | I16: ='รวมตาราง จ.อ่างทอง'!X96 -> 0 | K16: ยารักษาน้ำกัดเท้า (หลอด) | M16: ='รวมตาราง จ.อ่างทอง'!AM96 -> 390
B17: ให้บริการสุขศึกษา | C17: ='รวมตาราง จ.อ่างทอง'!L96 -> 595 | E17: เสี่ยงต่อการฆ่าตัวตาย | F17: ='รวมตาราง จ.อ่างทอง'!S96 -> 0 | H17: 4. โรคตาอักเสบ/ตาแดง | I17: ='รวมตาราง จ.อ่างทอง'!Y96 -> 5 | K17: ยาทากลากเกลื่อน (ชุด) | M17: ='รวมตาราง จ.อ่างทอง'!AN96 -> 0
B18: ตรวจรักษา | C18: ='รวมตาราง จ.อ่างทอง'!M96 -> 2 | E18: การให้ความช่วยเหลือ | H18: 5. โรคผิวหนัง เช่น แพ้ ผื่นคัน | I18: ='รวมตาราง จ.อ่างทอง'!Z96 -> 43 | K18: รองเท้าบูท (คู่) | M18: ='รวมตาราง จ.อ่างทอง'!AO96 -> 0
B19: การส่งต่อ | C19: ='รวมตาราง จ.อ่างทอง'!N96 -> 0 | E19: - ปฐมพยาบาลทางใจ (PFA) | F19: ='รวมตาราง จ.อ่างทอง'!T96 -> 28 | H19: 6. โรคน้ำกัดเท้า | I19: ='รวมตาราง จ.อ่างทอง'!AA96 -> 364 | K19: ยากันยุง (ซอง) | M19: ='รวมตาราง จ.อ่างทอง'!AP96 -> 36
B20: อื่นๆ | C20: ='รวมตาราง จ.อ่างทอง'!O96 -> 0 | E20: - พบแพทย์ | F20: ='รวมตาราง จ.อ่างทอง'!U96 -> 0 | H20: 7. ปวดเมื่อยกล้ามเนื้อ | I20: ='รวมตาราง จ.อ่างทอง'!AB96 -> 34 | K20: ถุงดำ | M20: ='รวมตาราง จ.อ่างทอง'!AQ96 -> 67
H21: 8. ปวดศรีษะ เวียนศรีษะ | I21: ='รวมตาราง จ.อ่างทอง'!AC96 -> 10 | K21: สารส้ม | M21: ='รวมตาราง จ.อ่างทอง'!AR96 -> 0
H22: 9. ไข้เลือดออก | I22: ='รวมตาราง จ.อ่างทอง'!AD96 -> 1 | K22: คลอรีน | M22: ='รวมตาราง จ.อ่างทอง'!AS96 -> 0
H23: 10. อุจจาระร่วงเฉียบพลัน/อาหารเป็นพิษ | I23: ='รวมตาราง จ.อ่างทอง'!AE96 -> 0 | K23: EM | M23: ='รวมตาราง จ.อ่างทอง'!AT96 -> 0
H24: 11. เหนื่อย อ่อนเพลีย | I24: ='รวมตาราง จ.อ่างทอง'!AF96 -> 0 | K24: อื่นๆ | M24: ='รวมตาราง จ.อ่างทอง'!AU96 -> 0
H25: 12. โรคที่เกิดจากการติดเชื้อไวรัส | I25: ='รวมตาราง จ.อ่างทอง'!AG96 -> 0
H26: 13. อื่นๆ ระบุ | I26: ='รวมตาราง จ.อ่างทอง'!AH96 -> 0
I28: =SUM(I14:I27) -> 457

Sheet เมือง
A1: แบบรายงานสถานการณ์อุทกภัย อำเภอ.....เมืองอ่างทอง...........จังหวัดอ่างทอง ปี 2569
B2: ** ขอให้สถานบริการบันทึกข้อมูล ภายในเวลา 15.00 น. ของทุกวัน **
A4: 1. สถานบริการสาธารณสุขที่ได้รับผลกระทบ จำนวน ..........-........ แห่ง (สถานบริการ หมายถึง สสจ. สสอ. รพศ. รพท. รพช. รพ.สต.และสถานบริการสังกัดกรมหรืออื่นๆ) | J4: ** สถานบริการบันทึก **
A6: ที่ | B6: ชื่อสถานบริการ | D6: ผลกระทบที่ได้รับ | E6: สถานะการให้บริการ | G6: ชื่อสถานที่ที่ให้บริการทดแทน (กรณี ปิดให้บริการ)
E7: เปิดบางส่วน | F7: ปิดบริการ
A8: 1
A9: 2
A10: 3
A11: 4
A12: 5
A14: 2. การดูแลกลุ่มเปราะบาง ** สถานบริการบันทึก **
A16: วันที่ | B16: ผู้ป่วยติดเตียง | G16: ผู้ป่วยฟอกไต | L16: จิตเวช (ที่ต้องรับยา) | Q16: ผู้สูงอายุ | W16: ผู้พิการ | AB16: ผู้ป่วยโรคเรื้อรัง (NCD) | AG16: หญิงตั้งครรภ์ | AL16: เด็กอายุ (0-5 ปี)
B17: จำนวนทั้งหมดในหมู่ (ราย) | C17: จำนวนในพื้นที่ที่น้ำท่วม (ราย) | D17: การให้ความช่วยเหลือ (ราย) | G17: จำนวนทั้งหมดในหมู่ (ราย) | H17: จำนวนในพื้นที่ที่น้ำท่วม (ราย) | I17: การให้ความช่วยเหลือ (ราย) | K17: ผู้ป่วยฟอกไตในพื้นที่น้ำท่วม | L17: จำนวนทั้งหมดในหมู่ (ราย) | M17: จำนวนในพื้นที่ที่น้ำท่วม (ราย) | N17: การให้ความช่วยเหลือ (ราย) | P17: จิตเวช (ที่ต้องรับยา)ในพื้นที่น้ำท่วม | Q17: จำนวนทั้งหมดในหมู่ (ราย) | R17: จำนวนในพื้นที่ที่น้ำท่วม (ราย) | S17: การให้ความช่วยเหลือ (ราย) | U17: ผู้สูงอายุที่มีโรคประจำตัวในพื้นที่น้ำท่วม | W17: จำนวนทั้งหมดในหมู่ (ราย) | X17: จำนวนในพื้นที่ที่น้ำท่วม (ราย) | Y17: การให้ความช่วยเหลือ (ราย) | AA17: ผู้พิการในพื้นที่น้ำท่วม | AB17: จำนวนทั้งหมดในหมู่ (ราย) | AC17: จำนวนในพื้นที่ที่น้ำท่วม (ราย) | AD17: การให้ความช่วยเหลือ (ราย) | AF17: ผู้ป่วยโรคเรื้อรัง (NCD)ในพื้นที่น้ำท่วม | AG17: จำนวนทั้งหมดในหมู่ (ราย) | AH17: จำนวนในพื้นที่ที่น้ำท่วม (ราย) | AI17: การให้ความช่วยเหลือ (ราย) | AK17: หญิงตั้งครรภ์ในพื้นที่น้ำท่วม | AL17: จำนวนทั้งหมดในหมู่ (ราย) | AM17: จำนวนในพื้นที่ที่น้ำท่วม (ราย) | AN17: การให้ความช่วยเหลือ (ราย) | AP17: เด็กอายุ (0-5 ปี) ในพื้นที่น้ำท่วม
D18: อยู่บ้าน (ราย) | E18: ศูนย์พักพิง (ราย) | F18: ส่งต่อ รพ. (ราย) | I18: อยู่บ้าน (ราย) | J18: อพยพ (ราย) | K18: ขาดการฟอกไต (ราย) | N18: อยู่บ้าน (ราย) | O18: อพยพ (ราย) | P18: พบปัญหาด้านสุขภาพ (ราย) | S18: อยู่บ้าน (ราย) | T18: อพยพ (ราย) | U18: จำนวนทั้งหมด (ราย) | V18: ขาดยา (ราย) | Y18: อยู่บ้าน (ราย) | Z18: อพยพ (ราย) | AA18: พบปัญหาด้านสุขภาพ (ราย) | AD18: อยู่บ้าน (ราย) | AE18: อพยพ (ราย) | AF18: ขาดยา (ราย) | AI18: อยู่บ้าน (ราย) | AJ18: อพยพ (ราย) | AK18: พบปัญหาด้านสุขภาพ (ราย) | AN18: อยู่บ้าน (ราย) | AO18: อพยพ (ราย) | AP18: พบปัญหาด้านสุขภาพ (ราย)
A19: 25475
A20: 25476 | B20: 18 | C20: 0 | D20: 0 | E20: 0 | F20: 0 | G20: 0 | H20: 0 | I20: 0 | J20: 0 | K20: 0 | L20: 9 | M20: 0 | N20: 0 | O20: 0 | P20: 0 | Q20: 1275 | R20: 19 | S20: 19 | T20: 0 | U20: 1 | V20: 0 | W20: 16 | X20: 1 | Y20: 1 | Z20: 0 | AA20: 0 | AB20: 299 | AC20: 7 | AD20: 7 | AE20: 0 | AF20: 0 | AG20: 0 | AH20: 0 | AI20: 0 | AJ20: 0 | AK20: 0 | AL20: 149 | AM20: 4 | AN20: 4 | AO20: 0 | AP20: 0
A21: 25477 | B21: 31 | C21: 0 | D21: 0 | E21: 0 | F21: 0 | G21: 1 | H21: 0 | I21: 1 | J21: 0 | K21: 0 | L21: 11 | M21: 0 | N21: 0 | O21: 0 | P21: 0 | Q21: 1612 | R21: 21 | S21: 21 | T21: 0 | U21: 8 | V21: 0 | W21: 119 | X21: 2 | Y21: 2 | Z21: 0 | AA21: 0 | AB21: 301 | AC21: 16 | AD21: 15 | AE21: 0 | AF21: 0 | AG21: 0 | AH21: 0 | AI21: 0 | AJ21: 0 | AK21: 0 | AL21: 148 | AM21: 4 | AN21: 4 | AO21: 0 | AP21: 0
A22: 25478 | B22: 48 | C22: 1 | D22: 1 | E22: 0 | F22: 0 | G22: 6 | H22: 0 | I22: 0 | J22: 0 | K22: 0 | L22: 127 | M22: 0 | N22: 0 | O22: 0 | P22: 0 | Q22: 2623 | R22: 27 | S22: 22 | T22: 0 | U22: 9 | V22: 0 | W22: 309 | X22: 2 | Y22: 2 | Z22: 0 | AA22: 0 | AB22: 1033 | AC22: 19 | AD22: 19 | AE22: 0 | AF22: 0 | AG22: 2 | AH22: 0 | AI22: 0 | AJ22: 0 | AK22: 0 | AL22: 278 | AM22: 3 | AN22: 3 | AO22: 0 | AP22: 0
A23: 25479
A24: 25480
A25: 25481
A26: 25482
A27: 25483
A28: 25484
A29: 25485
A30: 25486
A31: 25487
A32: 25488
A33: 25489
A34: 25490
... A52: 25508
B53: =SUM(B19:B52) -> 97 | C53: =SUM(C19:C52) -> 1 | D53: =SUM(D19:D52) -> 1 | E53: =SUM(E19:E52) -> 0 | F53: =SUM(F19:F52) -> 0 | G53: =SUM(G19:G52) -> 7 | H53: =SUM(H19:H52) -> 0 | I53: =SUM(I19:I52) -> 1 | ... AP53: =SUM(AP19:AP52) -> 0
A56: 3. การให้บริการด้านการแพทย์และสาธารณสุข ** สถานบริการบันทึก **
A58: สถานที่ออกหน่วย | B58: หมู่ที่ | C58: ชื่อหมู่บ้าน/ชุมชน | D58: จำนวนประชาชน ที่เข้ารับบริการ (คน) | E58: ทีมปฏิบัติการ | I58: การให้บริการด้านการแพทย์และสาธารณสุข (ราย) | P58: คัดกรองสุขภาพจิต (ราย) | V58: โรคที่พบบ่อยจากการออกหน่วยแพทย์เคลื่อนที่ (ราย) | AI58: อุบัติเหตุทางน้ำ | AK58: การสนับสนุนทรัพยากรให้แก่ประชาชน | AV58: จำนวน ศูนย์พักพิง (แห่ง) | AW58: ชื่อ-สกุลผู้รายงาน | AX58: เบอร์โทร
E59: หน่วยแพทย์เคลื่อนที่ | F59: MCATT | G59: SRRT | H59: ShERT
E60: จำนวน (ครั้ง) | F60: จำนวน (ครั้ง) | G60: จำนวน (ครั้ง) | H60: จำนวน (ครั้ง) | I60: จัดส่งยาโรคประจำตัว | J60: เยี่ยมบ้าน | K60: รับยา/แจกยา | L60: ให้บริการสุขศึกษา | M60: ตรวจรักษา | N60: การส่งต่อ | O60: อื่นๆ | P60: จำนวนผู้เข้ารับการคัดกรอง | Q60: เครียดสูง | R60: เสี่ยงซึมเศร้า | S60: เสี่ยงต่อการฆ่าตัวตาย | T60: การให้ความช่วยเหลือ | V60: 1. โรคระบบทางเดินหายใจ | W60: 2. โรคระบบทางเดินอาหาร | X60: 3. โรคระบบไหลเวียนโลหิต | Y60: 4. โรคตาอักเสบ/ตาแดง | Z60: 5. โรคผิวหนัง เช่น แพ้ ผื่นคัน | AA60: 6. โรคน้ำกัดเท้า | AB60: 7. ปวดเมื่อยกล้ามเนื้อ | AC60: 8. ปวดศรีษะ เวียนศรีษะ | AD60: 9. ไข้เลือดออก | AE60: 10. อุจจาระร่วงเฉียบพลัน/อาหารเป็นพิษ | AF60: 11. เหนื่อย อ่อนเพลีย | AG60: 12. โรคที่เกิดจากการติดเชื้อไวรัส | AH60: 13. อื่นๆ ระบุ | AI60: จมน้ำ (ราย) | AJ60: ไฟช๊อต (ราย) | AK60: ยาชุดช่วยเหลือผู้ประสบภัย (ชุด) | AL60: ยาสามัญประจำบ้าน (ชุด) | AM60: ยารักษาน้ำกัดเท้า (หลอด) | AN60: ยาทากลากเกลื่อน (ชุด) | AO60: รองเท้าบูท (คู่) | AP60: ยากันยุง (ซอง) | AQ60: ถุงดำ | AR60: สารส้ม | AS60: คลอรีน | AT60: EM | AU60: อื่นๆ
T61: ปฐมพยาบาลทางใจ (PFA) | U61: พบแพทย์
A62: 25475
A63: 25476 | D63: 18 | E63: 0 | F63: 0 | G63: 1 | H63: 0 | I63: 0 | J63: 2 | K63: 18 | L63: 18 | M63: 0 | N63: 0 | O63: 0 | P63: 0 | Q63: 0 | R63: 0 | S63: 0 | T63: 0 | U63: 0 | V63: 0 | W63: 0 | X63: 0 | Y63: 0 | Z63: 0 | AA63: 5 | AB63: 8 | AC63: 2 | AD63: 0 | AE63: 0 | AF63: 0 | AG63: 0 | AH63: 0 | AI63: 0 | AJ63: 0 | AK63: 10 | AL63: 0 | AM63: 0 | AN63: 0 | AO63: 0 | AP63: 0 | AQ63: 0 | AR63: 0 | AS63: 0 | AT63: 0 | AU63: 0 | AV63: 0
A64: 25477 | D64: 0 | E64: 2 | F64: 0 | G64: 0 | H64: 5 | I64: 12 | J64: 12 | K64: 0 | L64: 0 | M64: 0 | N64: 0 | O64: 0 | P64: 0 | Q64: 0 | R64: 0 | S64: 0 | T64: 0 | U64: 0 | V64: 0 | W64: 0 | X64: 0 | Y64: 5 | Z64: 9 | AA64: 2 | AB64: 0 | AC64: 0 | AD64: 0 | AE64: 0 | AF64: 0 | AG64: 0 | AH64: 0 | AI64: 11 | AJ64: 0 | AK64: 4 | AL64: 0 | AM64: 0 | AN64: 0 | AO64: 0 | AP64: 0 | AQ64: 0 | AR64: 0 | AS64: 0 | AT64: 0
...

Sheet ไชโย
A1: แบบรายงานสถานการณ์อุทกภัย อำเภอ.....เมืองอ่างทอง...........จังหวัดอ่างทอง ปี 2569
B2: ** ขอให้สถานบริการบันทึกข้อมูล ภายในเวลา 15.00 น. ของทุกวัน **
A4: 1. สถานบริการสาธารณสุขที่ได้รับผลกระทบ จำนวน ..........-........ แห่ง (สถานบริการ หมายถึง สสจ. สสอ. รพศ. รพท. รพช. รพ.สต.และสถานบริการสังกัดกรมหรืออื่นๆ) | J4: ** สถานบริการบันทึก **
A6: ที่ | B6: ชื่อสถานบริการ | D6: ผลกระทบที่ได้รับ | E6: สถานะการให้บริการ | G6: ชื่อสถานที่ที่ให้บริการทดแทน (กรณี ปิดให้บริการ)
E7: เปิดบางส่วน | F7: ปิดบริการ
A8: 1
A9: 2
A10: 3
A11: 4
A12: 5
A14: 2. การดูแลกลุ่มเปราะบาง ** สถานบริการบันทึก **
A16: วันที่ | B16: ผู้ป่วยติดเตียง | G16: ผู้ป่วยฟอกไต | L16: จิตเวช (ที่ต้องรับยา) | Q16: ผู้สูงอายุ | W16: ผู้พิการ | AB16: ผู้ป่วยโรคเรื้อรัง (NCD) | AG16: หญิงตั้งครรภ์ | AL16: เด็กอายุ (0-5 ปี)
B17: จำนวนทั้งหมดในหมู่ (ราย) | C17: จำนวนในพื้นที่ที่น้ำท่วม (ราย) | D17: การให้ความช่วยเหลือ (ราย) | G17: จำนวนทั้งหมดในหมู่ (ราย) | H17: จำนวนในพื้นที่ที่น้ำท่วม (ราย) | I17: การให้ความช่วยเหลือ (ราย) | K17: ผู้ป่วยฟอกไตในพื้นที่น้ำท่วม | L17: จำนวนทั้งหมดในหมู่ (ราย) | M17: จำนวนในพื้นที่ที่น้ำท่วม (ราย) | N17: การให้ความช่วยเหลือ (ราย) | P17: จิตเวช (ที่ต้องรับยา)ในพื้นที่น้ำท่วม | Q17: จำนวนทั้งหมดในหมู่ (ราย) | R17: จำนวนในพื้นที่ที่น้ำท่วม (ราย) | S17: การให้ความช่วยเหลือ (ราย) | U17: ผู้สูงอายุที่มีโรคประจำตัวในพื้นที่น้ำท่วม | W17: จำนวนทั้งหมดในหมู่ (ราย) | X17: จำนวนในพื้นที่ที่น้ำท่วม (ราย) | Y17: การให้ความช่วยเหลือ (ราย) | AA17: ผู้พิการในพื้นที่น้ำท่วม | AB17: จำนวนทั้งหมดในหมู่ (ราย) | AC17: จำนวนในพื้นที่ที่น้ำท่วม (ราย) | AD17: การให้ความช่วยเหลือ (ราย) | AF17: ผู้ป่วยโรคเรื้อรัง (NCD)ในพื้นที่น้ำท่วม | AG17: จำนวนทั้งหมดในหมู่ (ราย) | AH17: จำนวนในพื้นที่ที่น้ำท่วม (ราย) | AI17: การให้ความช่วยเหลือ (ราย) | AK17: หญิงตั้งครรภ์ในพื้นที่น้ำท่วม | AL17: จำนวนทั้งหมดในหมู่ (ราย) | AM17: จำนวนในพื้นที่ที่น้ำท่วม (ราย) | AN17: การให้ความช่วยเหลือ (ราย) | AP17: เด็กอายุ (0-5 ปี) ในพื้นที่น้ำท่วม
D18: อยู่บ้าน (ราย) | E18: ศูนย์พักพิง (ราย) | F18: ส่งต่อ รพ. (ราย) | I18: อยู่บ้าน (ราย) | J18: อพยพ (ราย) | K18: ขาดการฟอกไต (ราย) | N18: อยู่บ้าน (ราย) | O18: อพยพ (ราย) | P18: พบปัญหาด้านสุขภาพ (ราย) | S18: อยู่บ้าน (ราย) | T18: อพยพ (ราย) | U18: จำนวนทั้งหมด (ราย) | V18: ขาดยา (ราย) | Y18: อยู่บ้าน (ราย) | Z18: อพยพ (ราย) | AA18: พบปัญหาด้านสุขภาพ (ราย) | AD18: อยู่บ้าน (ราย) | AE18: อพยพ (ราย) | AF18: ขาดยา (ราย) | AI18: อยู่บ้าน (ราย) | AJ18: อพยพ (ราย) | AK18: พบปัญหาด้านสุขภาพ (ราย) | AN18: อยู่บ้าน (ราย) | AO18: อพยพ (ราย) | AP18: พบปัญหาด้านสุขภาพ (ราย)
A19: 25475 | S19: 10
A20: 25476 | B20: 25 | C20: 0 | D20: 0 | E20: 0 | F20: 0 | G20: 3 | H20: 0 | I20: 0 | J20: 0 | K20: 0 | L20: 64 | M20: 1 | N20: 1 | O20: 0 | P20: 0 | Q20: 612 | R20: 3 | S20: 27 | T20: 0 | U20: 24 | V20: 0 | W20: 231 | X20: 3 | Y20: 3 | Z20: 0 | AA20: 0 | AB20: 1620 | AC20: 46 | AD20: 46 | AE20: 0 | AF20: 0 | AG20: 16 | AH20: 2 | AI20: 2 | AJ20: 0 | AK20: 0 | AL20: 288 | AM20: 6 | AN20: 6 | AO20: 0 | AP20: 0
A21: 25477 | B21: 26 | C21: 0 | D21: 0 | E21: 0 | F21: 0 | G21: 2 | H21: 0 | I21: 0 | J21: 0 | K21: 0 | L21: 74 | M21: 1 | N21: 1 | O21: 0 | P21: 0 | Q21: 0 | R21: 0 | S21: 28 | T21: 0 | U21: 27 | V21: 0 | W21: 275 | X21: 8 | Y21: 8 | Z21: 0 | AA21: 2 | AB21: 1468 | AC21: 46 | AD21: 46 | AE21: 0 | AF21: 0 | AG21: 16 | AH21: 2 | AI21: 4 | AJ21: 0 | AK21: 0 | AL21: 302 | AM21: 10 | AN21: 10 | AO21: 4 | AP21: 0
A22: 25478
A23: 25479
A24: 25480
A25: 25481
A26: 25482
A27: 25483
A28: 25484
A29: 25485
A30: 25486
A31: 25487
A32: 25488
A33: 25489
... A52: 25508
B53: =SUM(B19:B52) -> 51 | C53: =SUM(C19:C52) -> 0 | D53: =SUM(D19:D52) -> 0 | E53: =SUM(E19:E52) -> 0 | F53: =SUM(F19:F52) -> 0 | G53: =SUM(G19:G52) -> 5 | H53: =SUM(H19:H52) -> 0 | I53: =SUM(I19:I52) -> 0 | ... AP53: =SUM(AP19:AP52) -> 0
A56: 3. การให้บริการด้านการแพทย์และสาธารณสุข ** สถานบริการบันทึก **
A58: สถานที่ออกหน่วย | B58: หมู่ที่ | C58: ชื่อหมู่บ้าน/ชุมชน | D58: จำนวนประชาชน ที่เข้ารับบริการ (คน) | E58: ทีมปฏิบัติการ | I58: การให้บริการด้านการแพทย์และสาธารณสุข (ราย) | P58: คัดกรองสุขภาพจิต (ราย) | V58: โรคที่พบบ่อยจากการออกหน่วยแพทย์เคลื่อนที่ (ราย) | AI58: อุบัติเหตุทางน้ำ | AK58: การสนับสนุนทรัพยากรให้แก่ประชาชน | AV58: จำนวน ศูนย์พักพิง (แห่ง) | AW58: ชื่อ-สกุลผู้รายงาน | AX58: เบอร์โทร
E59: หน่วยแพทย์เคลื่อนที่ | F59: MCATT | G59: SRRT | H59: ShERT
E60: จำนวน (ครั้ง) | F60: จำนวน (ครั้ง) | G60: จำนวน (ครั้ง) | H60: จำนวน (ครั้ง) | I60: จัดส่งยาโรคประจำตัว | J60: เยี่ยมบ้าน | K60: รับยา/แจกยา | L60: ให้บริการสุขศึกษา | M60: ตรวจรักษา | N60: การส่งต่อ | O60: อื่นๆ | P60: จำนวนผู้เข้ารับการคัดกรอง | Q60: เครียดสูง | R60: เสี่ยงซึมเศร้า | S60: เสี่ยงต่อการฆ่าตัวตาย | T60: การให้ความช่วยเหลือ | V60: 1. โรคระบบทางเดินหายใจ | W60: 2. โรคระบบทางเดินอาหาร | X60: 3. โรคระบบไหลเวียนโลหิต | Y60: 4. โรคตาอักเสบ/ตาแดง | Z60: 5. โรคผิวหนัง เช่น แพ้ ผื่นคัน | AA60: 6. โรคน้ำกัดเท้า | AB60: 7. ปวดเมื่อยกล้ามเนื้อ | AC60: 8. ปวดศรีษะ เวียนศรีษะ | AD60: 9. ไข้เลือดออก | AE60: 10. อุจจาระร่วงเฉียบพลัน/อาหารเป็นพิษ | AF60: 11. เหนื่อย อ่อนเพลีย | AG60: 12. โรคที่เกิดจากการติดเชื้อไวรัส | AH60: 13. อื่นๆ ระบุ | AI60: จมน้ำ (ราย) | AJ60: ไฟช๊อต (ราย) | AK60: ยาชุดช่วยเหลือผู้ประสบภัย (ชุด) | AL60: ยาสามัญประจำบ้าน (ชุด) | AM60: ยารักษาน้ำกัดเท้า (หลอด) | AN60: ยาทากลากเกลื่อน (ชุด) | AO60: รองเท้าบูท (คู่) | AP60: ยากันยุง (ซอง) | AQ60: ถุงดำ | AR60: สารส้ม | AS60: คลอรีน | AT60: EM | AU60: อื่นๆ
T61: ปฐมพยาบาลทางใจ (PFA) | U61: พบแพทย์
A62: 25475 | J62: 20 | K62: 10 | L62: 11 | AA62: 8
A63: 25476 | D63: 36 | E63: 0 | F63: 8 | G63: 4 | H63: 0 | I63: 0 | J63: 25 | K63: 0 | L63: 25 | M63: 0 | N63: 0 | O63: 0 | P63: 20 | Q63: 0 | R63: 0 | S63: 0 | T63: 0 | U63: 0 | V63: 0 | W63: 0 | X63: 0 | Y63: 0 | Z63: 4 | AA63: 2 | AB63: 4 | AC63: 3 | AD63: 0 | AE63: 0 | AF63: 0 | AG63: 0 | AH63: 0 | AI63: 0 | AJ63: 0 | AK63: 0 | AL63: 0 | AM63: 56 | AN63: 0 | AO63: 0 | AP63: 0 | AQ63: 0 | AR63: 0 | AS63: 0 | AT63: 0 | AU63: 0 | AV63: 1
A64: 25477 | D64: 22 | E64: 0 | F64: 7 | G64: 7 | H64: 0 | I64: 0 | J64: 33 | K64: 0 | L64: 33 | M64: 0 | N64: 0 | O64: 0 | P64: 0 | Q64: 0 | R64: 0 | S64: 0 | T64: 0 | U64: 0 | V64: 0 | W64: 0 | X64: 0 | Y64: 0 | Z64: 4 | AA64: 14 | AB64: 4 | AC64: 3 | AD64: 0 | AE64: 0 | AF64: 0 | AG64: 0 | AH64: 0 | AI64: 0 | AJ64: 0 | AK64: 0 | AL64: 0 | AM64: 44 | AN64: 0 | AO64: 0 | AP64: 0 | AQ64: 0 | AR64: 0 | AS64: 0 | AT64: 0 | AU64: 0 | AV64: 1
A65: 25478
...

Sheet ป่าโมก
A1: แบบรายงานสถานการณ์อุทกภัย อำเภอ.....เมืองอ่างทอง...........จังหวัดอ่างทอง ปี 2569
B2: ** ขอให้สถานบริการบันทึกข้อมูล ภายในเวลา 15.00 น. ของทุกวัน **
A4: 1. สถานบริการสาธารณสุขที่ได้รับผลกระทบ จำนวน ..........-........ แห่ง (สถานบริการ หมายถึง สสจ. สสอ. รพศ. รพท. รพช. รพ.สต.และสถานบริการสังกัดกรมหรืออื่นๆ) | J4: ** สถานบริการบันทึก **
A6: ที่ | B6: ชื่อสถานบริการ | D6: ผลกระทบที่ได้รับ | E6: สถานะการให้บริการ | G6: ชื่อสถานที่ที่ให้บริการทดแทน (กรณี ปิดให้บริการ)
E7: เปิดบางส่วน | F7: ปิดบริการ
A8: 1
A9: 2
A10: 3
A11: 4
A12: 5
A14: 2. การดูแลกลุ่มเปราะบาง ** สถานบริการบันทึก **
A16: วันที่ | B16: ผู้ป่วยติดเตียง | G16: ผู้ป่วยฟอกไต | L16: จิตเวช (ที่ต้องรับยา) | Q16: ผู้สูงอายุ | W16: ผู้พิการ | AB16: ผู้ป่วยโรคเรื้อรัง (NCD) | AG16: หญิงตั้งครรภ์ | AL16: เด็กอายุ (0-5 ปี)
B17: จำนวนทั้งหมดในหมู่ (ราย) | C17: จำนวนในพื้นที่ที่น้ำท่วม (ราย) | D17: การให้ความช่วยเหลือ (ราย) | G17: จำนวนทั้งหมดในหมู่ (ราย) | H17: จำนวนในพื้นที่ที่น้ำท่วม (ราย) | I17: การให้ความช่วยเหลือ (ราย) | K17: ผู้ป่วยฟอกไตในพื้นที่น้ำท่วม | L17: จำนวนทั้งหมดในหมู่ (ราย) | M17: จำนวนในพื้นที่ที่น้ำท่วม (ราย) | N17: การให้ความช่วยเหลือ (ราย) | P17: จิตเวช (ที่ต้องรับยา)ในพื้นที่น้ำท่วม | Q17: จำนวนทั้งหมดในหมู่ (ราย) | R17: จำนวนในพื้นที่ที่น้ำท่วม (ราย) | S17: การให้ความช่วยเหลือ (ราย) | U17: ผู้สูงอายุที่มีโรคประจำตัวในพื้นที่น้ำท่วม | W17: จำนวนทั้งหมดในหมู่ (ราย) | X17: จำนวนในพื้นที่ที่น้ำท่วม (ราย) | Y17: การให้ความช่วยเหลือ (ราย) | AA17: ผู้พิการในพื้นที่น้ำท่วม | AB17: จำนวนทั้งหมดในหมู่ (ราย) | AC17: จำนวนในพื้นที่ที่น้ำท่วม (ราย) | AD17: การให้ความช่วยเหลือ (ราย) | AF17: ผู้ป่วยโรคเรื้อรัง (NCD)ในพื้นที่น้ำท่วม | AG17: จำนวนทั้งหมดในหมู่ (ราย) | AH17: จำนวนในพื้นที่ที่น้ำท่วม (ราย) | AI17: การให้ความช่วยเหลือ (ราย) | AK17: หญิงตั้งครรภ์ในพื้นที่น้ำท่วม | AL17: จำนวนทั้งหมดในหมู่ (ราย) | AM17: จำนวนในพื้นที่ที่น้ำท่วม (ราย) | AN17: การให้ความช่วยเหลือ (ราย) | AP17: เด็กอายุ (0-5 ปี) ในพื้นที่น้ำท่วม
D18: อยู่บ้าน (ราย) | E18: ศูนย์พักพิง (ราย) | F18: ส่งต่อ รพ. (ราย) | I18: อยู่บ้าน (ราย) | J18: อพยพ (ราย) | K18: ขาดการฟอกไต (ราย) | N18: อยู่บ้าน (ราย) | O18: อพยพ (ราย) | P18: พบปัญหาด้านสุขภาพ (ราย) | S18: อยู่บ้าน (ราย) | T18: อพยพ (ราย) | U18: จำนวนทั้งหมด (ราย) | V18: ขาดยา (ราย) | Y18: อยู่บ้าน (ราย) | Z18: อพยพ (ราย) | AA18: พบปัญหาด้านสุขภาพ (ราย) | AD18: อยู่บ้าน (ราย) | AE18: อพยพ (ราย) | AF18: ขาดยา (ราย) | AI18: อยู่บ้าน (ราย) | AJ18: อพยพ (ราย) | AK18: พบปัญหาด้านสุขภาพ (ราย) | AN18: อยู่บ้าน (ราย) | AO18: อพยพ (ราย) | AP18: พบปัญหาด้านสุขภาพ (ราย)
A19: 25475 | H19: 1 | I19: 1 | M19: 4 | N19: 4 | S19: 19
A20: 25476 | B20: 52 | C20: 46 | D20: 10 | E20: 0 | F20: 0 | G20: 2 | H20: 1 | I20: 1 | J20: 0 | K20: 0 | L20: 26 | M20: 14 | N20: 10 | O20: 0 | P20: 0 | Q20: 88 | R20: 54 | S20: 275 | T20: 0 | U20: 153 | V20: 0 | W20: 104 | X20: 10 | Y20: 10 | Z20: 0 | AA20: 0 | AB20: 591 | AC20: 186 | AD20: 218 | AE20: 0 | AF20: 0 | AG20: 4 | AH20: 0 | AI20: 0 | AJ20: 0 | AK20: 0 | AL20: 114 | AM20: 15 | AN20: 70 | AO20: 0 | AP20: 0
A21: 25477 | B21: 17 | C21: 7 | D21: 7 | E21: 0 | F21: 0 | G21: 2 | H21: 1 | I21: 1 | J21: 0 | K21: 0 | L21: 22 | M21: 10 | N21: 10 | O21: 0 | P21: 0 | Q21: 1052 | R21: 262 | S21: 262 | T21: 0 | U21: 183 | V21: 0 | W21: 104 | X21: 10 | Y21: 10 | Z21: 0 | AA21: 0 | AB21: 628 | AC21: 183 | AD21: 183 | AE21: 0 | AF21: 0 | AG21: 4 | AH21: 0 | AI21: 0 | AJ21: 0 | AK21: 0 | AL21: 127 | AM21: 20 | AN21: 20 | AO21: 0 | AP21: 0
A22: 25478
A23: 25479
A24: 25480
A25: 25481
A26: 25482
A27: 25483
A28: 25484
A29: 25485
A30: 25486
A31: 25487
A32: 25488
A33: 25489
... A52: 25508
B53: =SUM(B19:B52) -> 69 | C53: =SUM(C19:C52) -> 53 | D53: =SUM(D19:D52) -> 17 | E53: =SUM(E19:E52) -> 0 | F53: =SUM(F19:F52) -> 0 | G53: =SUM(G19:G52) -> 4 | H53: =SUM(H19:H52) -> 3 | I53: =SUM(I19:I52) -> 3 | ... AP53: =SUM(AP19:AP52) -> 0
A56: 3. การให้บริการด้านการแพทย์และสาธารณสุข ** สถานบริการบันทึก **
A58: สถานที่ออกหน่วย | B58: หมู่ที่ | C58: ชื่อหมู่บ้าน/ชุมชน | D58: จำนวนประชาชน ที่เข้ารับบริการ (คน) | E58: ทีมปฏิบัติการ | I58: การให้บริการด้านการแพทย์และสาธารณสุข (ราย) | P58: คัดกรองสุขภาพจิต (ราย) | V58: โรคที่พบบ่อยจากการออกหน่วยแพทย์เคลื่อนที่ (ราย) | AI58: อุบัติเหตุทางน้ำ | AK58: การสนับสนุนทรัพยากรให้แก่ประชาชน | AV58: จำนวน ศูนย์พักพิง (แห่ง) | AW58: ชื่อ-สกุลผู้รายงาน | AX58: เบอร์โทร
E59: หน่วยแพทย์เคลื่อนที่ | F59: MCATT | G59: SRRT | H59: ShERT
E60: จำนวน (ครั้ง) | F60: จำนวน (ครั้ง) | G60: จำนวน (ครั้ง) | H60: จำนวน (ครั้ง) | I60: จัดส่งยาโรคประจำตัว | J60: เยี่ยมบ้าน | K60: รับยา/แจกยา | L60: ให้บริการสุขศึกษา | M60: ตรวจรักษา | N60: การส่งต่อ | O60: อื่นๆ | P60: จำนวนผู้เข้ารับการคัดกรอง | Q60: เครียดสูง | R60: เสี่ยงซึมเศร้า | S60: เสี่ยงต่อการฆ่าตัวตาย | T60: การให้ความช่วยเหลือ | V60: 1. โรคระบบทางเดินหายใจ | W60: 2. โรคระบบทางเดินอาหาร | X60: 3. โรคระบบไหลเวียนโลหิต | Y60: 4. โรคตาอักเสบ/ตาแดง | Z60: 5. โรคผิวหนัง เช่น แพ้ ผื่นคัน | AA60: 6. โรคน้ำกัดเท้า | AB60: 7. ปวดเมื่อยกล้ามเนื้อ | AC60: 8. ปวดศรีษะ เวียนศรีษะ | AD60: 9. ไข้เลือดออก | AE60: 10. อุจจาระร่วงเฉียบพลัน/อาหารเป็นพิษ | AF60: 11. เหนื่อย อ่อนเพลีย | AG60: 12. โรคที่เกิดจากการติดเชื้อไวรัส | AH60: 13. อื่นๆ ระบุ | AI60: จมน้ำ (ราย) | AJ60: ไฟช๊อต (ราย) | AK60: ยาชุดช่วยเหลือผู้ประสบภัย (ชุด) | AL60: ยาสามัญประจำบ้าน (ชุด) | AM60: ยารักษาน้ำกัดเท้า (หลอด) | AN60: ยาทากลากเกลื่อน (ชุด) | AO60: รองเท้าบูท (คู่) | AP60: ยากันยุง (ซอง) | AQ60: ถุงดำ | AR60: สารส้ม | AS60: คลอรีน | AT60: EM | AU60: อื่นๆ
T61: ปฐมพยาบาลทางใจ (PFA) | U61: พบแพทย์
A62: 25475 | J62: 20 | L62: 25 | P62: 40
A63: 25476 | D63: 114 | E63: 0 | F63: 0 | G63: 0 | H63: 0 | I63: 2 | J63: 50 | K63: 73 | L63: 75 | M63: 0 | N63: 0 | O63: 0 | P63: 6 | Q63: 0 | R63: 0 | S63: 0 | T63: 6 | U63: 0 | V63: 0 | W63: 0 | X63: 0 | Y63: 0 | Z63: 0 | AA63: 0 | AB63: 0 | AC63: 0 | AD63: 0 | AE63: 0 | AF63: 0 | AG63: 0 | AH63: 0 | AI63: 0 | AJ63: 0 | AK63: 18 | AL63: 0 | AM63: 78 | AN63: 0 | AO63: 0 | AP63: 36 | AQ63: 54 | AR63: 0 | AS63: 0 | AT63: 0 | AU63: 0 | AV63: 0
A64: 25477 | D64: 11 | E64: 0 | F64: 0 | G64: 0 | H64: 0 | I64: 11 | J64: 0 | K64: 22 | L64: 0 | M64: 0 | N64: 0 | O64: 0 | P64: 0 | Q64: 0 | R64: 0 | S64: 0 | T64: 0 | U64: 0 | V64: 0 | W64: 0 | X64: 0 | Y64: 0 | Z64: 0 | AA64: 0 | AB64: 0 | AC64: 0 | AD64: 0 | AE64: 0 | AF64: 0 | AG64: 0 | AH64: 0 | AI64: 0 | AJ64: 0 | AK64: 0 | AL64: 0 | AM64: 0 | AN64: 0 | AO64: 0 | AP64: 0 | AQ64: 0 | AR64: 0 | AS64: 0 | AT64: 0 | AU64: 0 | AV64: 0
A65: 25478
...

Sheet โพธิ์ทอง
A1: แบบรายงานสถานการณ์อุทกภัย อำเภอ.....เมืองอ่างทอง...........จังหวัดอ่างทอง ปี 2569
B2: ** ขอให้สถานบริการบันทึกข้อมูล ภายในเวลา 15.00 น. ของทุกวัน **
A4: 1. สถานบริการสาธารณสุขที่ได้รับผลกระทบ จำนวน ..........-........ แห่ง (สถานบริการ หมายถึง สสจ. สสอ. รพศ. รพท. รพช. รพ.สต.และสถานบริการสังกัดกรมหรืออื่นๆ) | J4: ** สถานบริการบันทึก **
A6: ที่ | B6: ชื่อสถานบริการ | D6: ผลกระทบที่ได้รับ | E6: สถานะการให้บริการ | G6: ชื่อสถานที่ที่ให้บริการทดแทน (กรณี ปิดให้บริการ)
E7: เปิดบางส่วน | F7: ปิดบริการ
A8: 1
A9: 2
A10: 3
A11: 4
A12: 5
A14: 2. การดูแลกลุ่มเปราะบาง ** สถานบริการบันทึก **
A16: วันที่ | B16: ผู้ป่วยติดเตียง | G16: ผู้ป่วยฟอกไต | L16: จิตเวช (ที่ต้องรับยา) | Q16: ผู้สูงอายุ | W16: ผู้พิการ | AB16: ผู้ป่วยโรคเรื้อรัง (NCD) | AG16: หญิงตั้งครรภ์ | AL16: เด็กอายุ (0-5 ปี)
B17: จำนวนทั้งหมดในหมู่ (ราย) | C17: จำนวนในพื้นที่ที่น้ำท่วม (ราย) | D17: การให้ความช่วยเหลือ (ราย) | G17: จำนวนทั้งหมดในหมู่ (ราย) | H17: จำนวนในพื้นที่ที่น้ำท่วม (ราย) | I17: การให้ความช่วยเหลือ (ราย) | K17: ผู้ป่วยฟอกไตในพื้นที่น้ำท่วม | L17: จำนวนทั้งหมดในหมู่ (ราย) | M17: จำนวนในพื้นที่ที่น้ำท่วม (ราย) | N17: การให้ความช่วยเหลือ (ราย) | P17: จิตเวช (ที่ต้องรับยา)ในพื้นที่น้ำท่วม | Q17: จำนวนทั้งหมดในหมู่ (ราย) | R17: จำนวนในพื้นที่ที่น้ำท่วม (ราย) | S17: การให้ความช่วยเหลือ (ราย) | U17: ผู้สูงอายุที่มีโรคประจำตัวในพื้นที่น้ำท่วม | W17: จำนวนทั้งหมดในหมู่ (ราย) | X17: จำนวนในพื้นที่ที่น้ำท่วม (ราย) | Y17: การให้ความช่วยเหลือ (ราย) | AA17: ผู้พิการในพื้นที่น้ำท่วม | AB17: จำนวนทั้งหมดในหมู่ (ราย) | AC17: จำนวนในพื้นที่ที่น้ำท่วม (ราย) | AD17: การให้ความช่วยเหลือ (ราย) | AF17: ผู้ป่วยโรคเรื้อรัง (NCD)ในพื้นที่น้ำท่วม | AG17: จำนวนทั้งหมดในหมู่ (ราย) | AH17: จำนวนในพื้นที่ที่น้ำท่วม (ราย) | AI17: การให้ความช่วยเหลือ (ราย) | AK17: หญิงตั้งครรภ์ในพื้นที่น้ำท่วม | AL17: จำนวนทั้งหมดในหมู่ (ราย) | AM17: จำนวนในพื้นที่ที่น้ำท่วม (ราย) | AN17: การให้ความช่วยเหลือ (ราย) | AP17: เด็กอายุ (0-5 ปี) ในพื้นที่น้ำท่วม
D18: อยู่บ้าน (ราย) | E18: ศูนย์พักพิง (ราย) | F18: ส่งต่อ รพ. (ราย) | I18: อยู่บ้าน (ราย) | J18: อพยพ (ราย) | K18: ขาดการฟอกไต (ราย) | N18: อยู่บ้าน (ราย) | O18: อพยพ (ราย) | P18: พบปัญหาด้านสุขภาพ (ราย) | S18: อยู่บ้าน (ราย) | T18: อพยพ (ราย) | U18: จำนวนทั้งหมด (ราย) | V18: ขาดยา (ราย) | Y18: อยู่บ้าน (ราย) | Z18: อพยพ (ราย) | AA18: พบปัญหาด้านสุขภาพ (ราย) | AD18: อยู่บ้าน (ราย) | AE18: อพยพ (ราย) | AF18: ขาดยา (ราย) | AI18: อยู่บ้าน (ราย) | AJ18: อพยพ (ราย) | AK18: พบปัญหาด้านสุขภาพ (ราย) | AN18: อยู่บ้าน (ราย) | AO18: อพยพ (ราย) | AP18: พบปัญหาด้านสุขภาพ (ราย)
A19: 25475
A20: 25476 | B20: 2 | C20: 0 | G20: 0 | H20: 0 | L20: 0 | M20: 0 | Q20: 102 | R20: 4 | S20: 4 | T20: 0 | U20: 4 | V20: 0 | W20: 10 | X20: 0 | Y20: 0 | Z20: 0 | AA20: 0 | AB20: 90 | AC20: 4 | AD20: 4 | AE20: 0 | AF20: 0 | AG20: 1 | AH20: 0 | AI20: 0 | AJ20: 0 | AK20: 0 | AL20: 9 | AM20: 0 | AN20: 0 | AO20: 0 | AP20: 0
A21: 25477 | B21: 2 | C21: 0 | D21: 0 | E21: 0 | F21: 0 | G21: 0 | H21: 0 | I21: 0 | J21: 0 | K21: 0 | L21: 0 | M21: 0 | N21: 0 | O21: 0 | P21: 0 | Q21: 102 | R21: 4 | S21: 4 | T21: 0 | U21: 4 | V21: 0 | W21: 10 | X21: 0 | Y21: 0 | Z21: 0 | AA21: 0 | AB21: 90 | AC21: 4 | AD21: 4 | AE21: 0 | AF21: 0 | AG21: 1 | AH21: 0 | AI21: 0 | AJ21: 0 | AK21: 0 | AL21: 9 | AM21: 0 | AN21: 0 | AO21: 0 | AP21: 0
A22: 25478 | B22: 2 | C22: 0 | D22: 0 | E22: 0 | F22: 0 | G22: 0 | H22: 0 | I22: 0 | J22: 0 | K22: 0 | L22: 0 | M22: 0 | N22: 0 | O22: 0 | P22: 0 | Q22: 102 | R22: 4 | S22: 4 | T22: 0 | U22: 4 | V22: 0 | W22: 10 | X22: 0 | Y22: 0 | Z22: 0 | AA22: 0 | AB22: 90 | AC22: 4 | AD22: 4 | AE22: 0 | AF22: 0 | AG22: 1 | AH22: 0 | AI22: 0 | AJ22: 0 | AK22: 0 | AL22: 9 | AM22: 0 | AN22: 0 | AO22: 0 | AP22: 0
A23: 25479
A24: 25480
A25: 25481
A26: 25482
A27: 25483
A28: 25484
A29: 25485
A30: 25486
A31: 25487
A32: 25488
A33: 25489
A34: 25490
... A52: 25508
B53: =SUM(B19:B52) -> 6 | C53: =SUM(C19:C52) -> 0 | D53: =SUM(D19:D52) -> 0 | E53: =SUM(E19:E52) -> 0 | F53: =SUM(F19:F52) -> 0 | G53: =SUM(G19:G52) -> 0 | H53: =SUM(H19:H52) -> 0 | I53: =SUM(I19:I52) -> 0 | ... AP53: =SUM(AP19:AP52) -> 0
A56: 3. การให้บริการด้านการแพทย์และสาธารณสุข ** สถานบริการบันทึก **
A58: สถานที่ออกหน่วย | B58: หมู่ที่ | C58: ชื่อหมู่บ้าน/ชุมชน | D58: จำนวนประชาชน ที่เข้ารับบริการ (คน) | E58: ทีมปฏิบัติการ | I58: การให้บริการด้านการแพทย์และสาธารณสุข (ราย) | P58: คัดกรองสุขภาพจิต (ราย) | V58: โรคที่พบบ่อยจากการออกหน่วยแพทย์เคลื่อนที่ (ราย) | AI58: อุบัติเหตุทางน้ำ | AK58: การสนับสนุนทรัพยากรให้แก่ประชาชน | AV58: จำนวน ศูนย์พักพิง (แห่ง) | AW58: ชื่อ-สกุลผู้รายงาน | AX58: เบอร์โทร
E59: หน่วยแพทย์เคลื่อนที่ | F59: MCATT | G59: SRRT | H59: ShERT
E60: จำนวน (ครั้ง) | F60: จำนวน (ครั้ง) | G60: จำนวน (ครั้ง) | H60: จำนวน (ครั้ง) | I60: จัดส่งยาโรคประจำตัว | J60: เยี่ยมบ้าน | K60: รับยา/แจกยา | L60: ให้บริการสุขศึกษา | M60: ตรวจรักษา | N60: การส่งต่อ | O60: อื่นๆ | P60: จำนวนผู้เข้ารับการคัดกรอง | Q60: เครียดสูง | R60: เสี่ยงซึมเศร้า | S60: เสี่ยงต่อการฆ่าตัวตาย | T60: การให้ความช่วยเหลือ | V60: 1. โรคระบบทางเดินหายใจ | W60: 2. โรคระบบทางเดินอาหาร | X60: 3. โรคระบบไหลเวียนโลหิต | Y60: 4. โรคตาอักเสบ/ตาแดง | Z60: 5. โรคผิวหนัง เช่น แพ้ ผื่นคัน | AA60: 6. โรคน้ำกัดเท้า | AB60: 7. ปวดเมื่อยกล้ามเนื้อ | AC60: 8. ปวดศรีษะ เวียนศรีษะ | AD60: 9. ไข้เลือดออก | AE60: 10. อุจจาระร่วงเฉียบพลัน/อาหารเป็นพิษ | AF60: 11. เหนื่อย อ่อนเพลีย | AG60: 12. โรคที่เกิดจากการติดเชื้อไวรัส | AH60: 13. อื่นๆ ระบุ | AI60: จมน้ำ (ราย) | AJ60: ไฟช๊อต (ราย) | AK60: ยาชุดช่วยเหลือผู้ประสบภัย (ชุด) | AL60: ยาสามัญประจำบ้าน (ชุด) | AM60: ยารักษาน้ำกัดเท้า (หลอด) | AN60: ยาทากลากเกลื่อน (ชุด) | AO60: รองเท้าบูท (คู่) | AP60: ยากันยุง (ซอง) | AQ60: ถุงดำ | AR60: สารส้ม | AS60: คลอรีน | AT60: EM | AU60: อื่นๆ
T61: ปฐมพยาบาลทางใจ (PFA) | U61: พบแพทย์
A62: 25475
A63: 25476 | D63: 4 | E63: 0 | F63: 0 | G63: 0 | H63: 0 | I63: 0 | J63: 4 | K63: 4 | L63: 4 | M63: 0 | N63: 0 | O63: 0 | P63: 0 | Q63: 0 | R63: 0 | S63: 0 | T63: 0 | U63: 0 | V63: 0 | W63: 0 | X63: 0 | Y63: 0 | Z63: 0 | AA63: 0 | AB63: 0 | AC63: 0 | AD63: 0 | AE63: 0 | AF63: 0 | AG63: 0 | AH63: 0 | AI63: 0 | AJ63: 0 | AK63: 0 | AL63: 0 | AM63: 4 | AN63: 0 | AO63: 0 | AP63: 0 | AQ63: 0 | AR63: 0 | AS63: 0 | AT63: 0 | AU63: 0 | AV63: 0
A64: 25477 | D64: 4 | E64: 0 | F64: 0 | G64: 0 | H64: 0 | I64: 0 | J64: 4 | K64: 4 | L64: 4 | M64: 0 | N64: 0 | O64: 0 | P64: 0 | Q64: 0 | R64: 0 | S64: 0 | T64: 0 | U64: 0 | V64: 0 | W64: 0 | X64: 0 | Y64: 0 | Z64: 0 | AA64: 0 | AB64: 0 | AC64: 0 | AD64: 0 | AE64: 0 | AF64: 0 | AG64: 0 | AH64: 0 | AI64: 0 | AJ64: 0 | AK64: 0 | AL64: 0 | AM64: 4 | AN64: 0 | AO64: 0 | AP64: 0 | AQ64: 0 | AR64: 0 | AS64: 0 | AT64: 0 | AU64: 0 | AV64: 0
...

Sheet วิเศษ
A1: แบบรายงานสถานการณ์อุทกภัย อำเภอ.....เมืองอ่างทอง...........จังหวัดอ่างทอง ปี 2569
B2: ** ขอให้สถานบริการบันทึกข้อมูล ภายในเวลา 15.00 น. ของทุกวัน **
A4: 1. สถานบริการสาธารณสุขที่ได้รับผลกระทบ จำนวน ..........-........ แห่ง (สถานบริการ หมายถึง สสจ. สสอ. รพศ. รพท. รพช. รพ.สต.และสถานบริการสังกัดกรมหรืออื่นๆ) | J4: ** สถานบริการบันทึก **
A6: ที่ | B6: ชื่อสถานบริการ | D6: ผลกระทบที่ได้รับ | E6: สถานะการให้บริการ | G6: ชื่อสถานที่ที่ให้บริการทดแทน (กรณี ปิดให้บริการ) | R6: ผู้สูงอายุ
E7: เปิดบางส่วน | F7: ปิดบริการ | R7: จำนวนทั้งหมด (ราย) | S7: จำนวนในพื้นที่ที่น้ำท่วม (ราย)
A8: 1 | S8: อยู่บ้าน (ราย)
A9: 2 | R9: 1345 | S9: 368
A10: 3 | R10: 456 | S10: 10
A11: 4 | R11: 19 | S11: 19
A12: 5 | R12: 1820 | S12: 397
A14: 2. การดูแลกลุ่มเปราะบาง ** สถานบริการบันทึก **
A16: วันที่ | B16: ผู้ป่วยติดเตียง | G16: ผู้ป่วยฟอกไต | L16: จิตเวช (ที่ต้องรับยา) | Q16: ผู้สูงอายุ | W16: ผู้พิการ | AB16: ผู้ป่วยโรคเรื้อรัง (NCD) | AG16: หญิงตั้งครรภ์ | AL16: เด็กอายุ (0-5 ปี)
B17: จำนวนทั้งหมดในหมู่ (ราย) | C17: จำนวนในพื้นที่ที่น้ำท่วม (ราย) | D17: การให้ความช่วยเหลือ (ราย) | G17: จำนวนทั้งหมดในหมู่ (ราย) | H17: จำนวนในพื้นที่ที่น้ำท่วม (ราย) | I17: การให้ความช่วยเหลือ (ราย) | K17: ผู้ป่วยฟอกไตในพื้นที่น้ำท่วม | L17: จำนวนทั้งหมดในหมู่ (ราย) | M17: จำนวนในพื้นที่ที่น้ำท่วม (ราย) | N17: การให้ความช่วยเหลือ (ราย) | P17: จิตเวช (ที่ต้องรับยา)ในพื้นที่น้ำท่วม | Q17: จำนวนทั้งหมดในหมู่ (ราย) | R17: จำนวนในพื้นที่ที่น้ำท่วม (ราย) | S17: การให้ความช่วยเหลือ (ราย) | U17: ผู้สูงอายุที่มีโรคประจำตัวในพื้นที่น้ำท่วม | W17: จำนวนทั้งหมดในหมู่ (ราย) | X17: จำนวนในพื้นที่ที่น้ำท่วม (ราย) | Y17: การให้ความช่วยเหลือ (ราย) | AA17: ผู้พิการในพื้นที่น้ำท่วม | AB17: จำนวนทั้งหมดในหมู่ (ราย) | AC17: จำนวนในพื้นที่ที่น้ำท่วม (ราย) | AD17: การให้ความช่วยเหลือ (ราย) | AF17: ผู้ป่วยโรคเรื้อรัง (NCD)ในพื้นที่น้ำท่วม | AG17: จำนวนทั้งหมดในหมู่ (ราย) | AH17: จำนวนในพื้นที่ที่น้ำท่วม (ราย) | AI17: การให้ความช่วยเหลือ (ราย) | AK17: หญิงตั้งครรภ์ในพื้นที่น้ำท่วม | AL17: จำนวนทั้งหมดในหมู่ (ราย) | AM17: จำนวนในพื้นที่ที่น้ำท่วม (ราย) | AN17: การให้ความช่วยเหลือ (ราย) | AP17: เด็กอายุ (0-5 ปี) ในพื้นที่น้ำท่วม
D18: อยู่บ้าน (ราย) | E18: ศูนย์พักพิง (ราย) | F18: ส่งต่อ รพ. (ราย) | I18: อยู่บ้าน (ราย) | J18: อพยพ (ราย) | K18: ขาดการฟอกไต (ราย) | N18: อยู่บ้าน (ราย) | O18: อพยพ (ราย) | P18: พบปัญหาด้านสุขภาพ (ราย) | S18: อยู่บ้าน (ราย) | T18: อพยพ (ราย) | U18: จำนวนทั้งหมด (ราย) | V18: ขาดยา (ราย) | Y18: อยู่บ้าน (ราย) | Z18: อพยพ (ราย) | AA18: พบปัญหาด้านสุขภาพ (ราย) | AD18: อยู่บ้าน (ราย) | AE18: อพยพ (ราย) | AF18: ขาดยา (ราย) | AI18: อยู่บ้าน (ราย) | AJ18: อพยพ (ราย) | AK18: พบปัญหาด้านสุขภาพ (ราย) | AN18: อยู่บ้าน (ราย) | AO18: อพยพ (ราย) | AP18: พบปัญหาด้านสุขภาพ (ราย)
A19: 25475 | C19: 19 | D19: 19 | H19: 1 | I19: 1 | M19: 3 | N19: 3 | R19: 368 | S19: 368 | X19: 22 | Y19: 22 | AH19: 3 | AI19: 3
A20: 25476 | B20: 90 | C20: 32 | D20: 32 | E20: 0 | F20: 0 | G20: 12 | H20: 0 | I20: 0 | J20: 0 | K20: 0 | L20: 38 | M20: 8 | N20: 8 | O20: 0 | P20: 0 | Q20: 0 | R20: 0 | S20: 450 | T20: 0 | U20: 1312 | V20: 0 | W20: 310 | X20: 42 | Y20: 42 | Z20: 0 | AA20: 0 | AB20: 1612 | AC20: 66 | AD20: 66 | AE20: 0 | AF20: 0 | AG20: 0 | AH20: 0 | AI20: 0 | AJ20: 0 | AK20: 0 | AL20: 122 | AM20: 10 | AN20: 10 | AO20: 0 | AP20: 0
A21: 25477 | B21: 90 | C21: 32 | D21: 32 | E21: 0 | F21: 0 | G21: 12 | H21: 0 | I21: 0 | J21: 0 | K21: 0 | L21: 38 | M21: 8 | N21: 8 | O21: 0 | P21: 0 | Q21: 0 | R21: 0 | S21: 450 | T21: 0 | U21: 1312 | V21: 0 | W21: 310 | X21: 42 | Y21: 42 | Z21: 0 | AA21: 0 | AB21: 1612 | AC21: 66 | AD21: 66 | AE21: 0 | AF21: 0 | AG21: 0 | AH21: 0 | AI21: 0 | AJ21: 0 | AK21: 0 | AL21: 122 | AM21: 10 | AN21: 10 | AO21: 0 | AP21: 0
A22: 25478
A23: 25479
A24: 25480
A25: 25481
A26: 25482
A27: 25483
A28: 25484
A29: 25485
A30: 25486
A31: 25487
A32: 25488
A33: 25489
... A52: 25508
B53: 90 | C53: 32 | D53: 32 | E53: 0 | F53: 0 | G53: 12 | H53: 0 | I53: 0 | J53: 0 | K53: 0 | L53: 38 | M53: 8 | N53: 10 | O53: 0 | P53: 0 | Q53: 0 | R53: 0 | S53: 450 | T53: 0 | U53: 1312 | V53: 0 | W53: 310 | X53: 42 | Y53: 42 | Z53: 0 | AA53: 0 | AB53: 1612 | AC53: 66 | AD53: 16 | AE53: 0 | AF53: 0 | AG53: 0 | AH53: 0 | AI53: 0 | AJ53: 0 | AK53: 0 | AL53: 122 | AM53: 10 | AN53: 10 | AO53: 0 | AP53: 0
A56: 3. การให้บริการด้านการแพทย์และสาธารณสุข ** สถานบริการบันทึก **
